Workbook

Sheet GDP per capita long
E1: 1960 | F1: =E1+1 -> 1961 | G1: =F1+1 -> 1962 | H1: =G1+1 -> 1963 | I1: =H1+1 -> 1964 | J1: =I1+1 -> 1965 | K1: =J1+1 -> 1966 | L1: =K1+1 -> 1967 | M1: =L1+1 -> 1968 | ... BQ1: =BP1+1 -> 2024
A2: Country Name | B2: Country Code | C2: Series Name | D2: Series Code | E2: 1960 [YR1960] | F2: 1961 [YR1961] | G2: 1962 [YR1962] | H2: 1963 [YR1963] | I2: 1964 [YR1964] | J2: 1965 [YR1965] | K2: 1966 [YR1966] | L2: 1967 [YR1967] | M2: 1968 [YR1968] | N2: 1969 [YR1969] | O2: 1970 [YR1970] | P2: 1971 [YR1971] | Q2: 1972 [YR1972] | R2: 1973 [YR1973] | S2: 1974 [YR1974] | T2: 1975 [YR1975] | U2: 1976 [YR1976] | V2: 1977 [YR1977] | W2: 1978 [YR1978] | X2: 1979 [YR1979] | Y2: 1980 [YR1980] | Z2: 1981 [YR1981] | AA2: 1982 [YR1982] | AB2: 1983 [YR1983] | AC2: 1984 [YR1984] | AD2: 1985 [YR1985] | AE2: 1986 [YR1986] | AF2: 1987 [YR1987] | AG2: 1988 [YR1988] | AH2: 1989 [YR1989] | AI2: 1990 [YR1990] | AJ2: 1991 [YR1991] | AK2: 1992 [YR1992] | AL2: 1993 [YR1993] | AM2: 1994 [YR1994] | AN2: 1995 [YR1995] | AO2: 1996 [YR1996] | AP2: 1997 [YR1997] | AQ2: 1998 [YR1998] | AR2: 1999 [YR1999] | AS2: 2000 [YR2000] | AT2: 2001 [YR2001] | AU2: 2002 [YR2002] | AV2: 2003 [YR2003] | AW2: 2004 [YR2004] | AX2: 2005 [YR2005] | AY2: 2006 [YR2006] | AZ2: 2007 [YR2007] | BA2: 2008 [YR2008] | BB2: 2009 [YR2009] | BC2: 2010 [YR2010] | BD2: 2011 [YR2011] | BE2: 2012 [YR2012] | BF2: 2013 [YR2013] | BG2: 2014 [YR2014] | BH2: 2015 [YR2015] | BI2: 2016 [YR2016] | BJ2: 2017 [YR2017] | BK2: 2018 [YR2018] | BL2: 2019 [YR2019] | BM2: 2020 [YR2020] | BN2: 2021 [YR2021] | BO2: 2022 [YR2022] | BP2: 2023 [YR2023] | BQ2: 2024 [YR2024]
A3: Mexico | B3: MEX | C3: GDP per capita (constant LCU) | D3: NY.GDP.PCAP.KN | E3: 78139.839 | F3: 79523.064 | G3: 80596.678 | H3: 84339.591 | I3: 91334.962 | J3: 94642.285 | K3: 97139.015 | L3: 99481.697 | M3: 105342.35 | N3: 105480.8 | O3: 108842.78 | P3: 109495.45 | Q3: 114957.68 | R3: 120348.09 | S3: 123629.6 | T3: 127047.19 | U3: 129021.44 | V3: 129835.82 | W3: 137771.36 | X3: 147288.5 | Y3: 156255.23 | Z3: 167277.2 | AA3: 163535.87 | AB3: 152640.7 | AC3: 154702.81 | AD3: 154443.44 | AE3: 145386.04 | AF3: 145440.42 | AG3: 144332.72 | AH3: 146709.04 | AI3: 151478.63 | AJ3: 154497.14 | AK3: 157008.68 | AL3: 158545.4 | AM3: 162535.22 | AN3: 150230.5 | AO3: 156827.53 | AP3: 165312.74 | AQ3: 172683.25 | AR3: 174626.14 | AS3: 180600.81 | AT3: 177139.96 | AU3: 174198.32 | AV3: 173816.04 | AW3: 177572.32 | AX3: 178895.96 | AY3: 184970.87 | AZ3: 186174.64 | BA3: 185206.74 | BB3: 171028.84 | BC3: 176964.99 | BD3: 180487.05 | BE3: 184380.73 | BF3: 183555.06 | BG3: 185887.89 | BH3: 188880.14 | BI3: 190374.1 | BJ3: 192132.06 | BK3: 194075.22 | BL3: 191485.05 | BM3: 174054.41 | BN3: 183354.26 | BO3: 188731.77 | BP3: 193258.3 | BQ3: 194388.43
A7: Data from database: World Development Indicators
A8: Last Updated: 07/01/2025 | G8: rho | H8: 0.5748 | J8: drop in 1982 | K8: =E39/E38-1 -> -0.02236604
G9: sigma | H9: 0.0256 | J9: drop in 1983 | K9: =E40/E39-1 -> -0.066622502
J10: drop in 1983 from 1981 | K10: =E40/E38-1 -> -0.08749846
J11: drop in 1982 from linear trend pre default | K11: =J39 -> 0.0069613579
J12: drop in 1983 from linear trend pre default | K12: =J40 -> -0.095455005
I14: intercept | J14: -54.341319
I15: slope | J15: 0.03347081
E16: gdp | F16: log | G16: trend | H16: cycle | I16: log_lin_trend | J16: log deviation from linear trend
D17: 1960 | E17: =HLOOKUP(D17,$E$1:$BQ$3,3,FALSE) -> 78139.839 | F17: =LN(E17) -> 11.266255 | G17: 11.255054 | H17: =F17-G17 -> 0.011201643 | I17: =$J$14+$J$15*D17 -> 11.261468 | J17: =F17-I17 -> 0.004786828
D18: =D17+1 -> 1961 | E18: =HLOOKUP(D18,$E$1:$BQ$3,3,FALSE) -> 79523.064 | F18: =LN(E18) -> 11.283802 | G18: 11.291325 | H18: =F18-G18 -> -0.0075223265 | I18: =$J$14+$J$15*D18 -> 11.294939 | J18: =F18-I18 -> -0.011136918
D19: =D18+1 -> 1962 | E19: =HLOOKUP(D19,$E$1:$BQ$3,3,FALSE) -> 80596.678 | F19: =LN(E19) -> 11.297213 | G19: 11.327708 | H19: =F19-G19 -> -0.030495033 | I19: =$J$14+$J$15*D19 -> 11.32841 | J19: =F19-I19 -> -0.031197385
D20: =D19+1 -> 1963 | E20: =HLOOKUP(D20,$E$1:$BQ$3,3,FALSE) -> 84339.591 | F20: =LN(E20) -> 11.342607 | G20: 11.36424 | H20: =F20-G20 -> -0.021632931 | I20: =$J$14+$J$15*D20 -> 11.361881 | J20: =F20-I20 -> -0.019274234
D21: =D20+1 -> 1964 | E21: =HLOOKUP(D21,$E$1:$BQ$3,3,FALSE) -> 91334.962 | F21: =LN(E21) -> 11.422289 | G21: 11.400652 | H21: =F21-G21 -> 0.021636809 | I21: =$J$14+$J$15*D21 -> 11.395352 | J21: =F21-I21 -> 0.026937207
D22: =D21+1 -> 1965 | E22: =HLOOKUP(D22,$E$1:$BQ$3,3,FALSE) -> 94642.285 | F22: =LN(E22) -> 11.45786 | G22: 11.436461 | H22: =F22-G22 -> 0.021398844 | I22: =$J$14+$J$15*D22 -> 11.428823 | J22: =F22-I22 -> 0.02903711
D23: =D22+1 -> 1966 | E23: =HLOOKUP(D23,$E$1:$BQ$3,3,FALSE) -> 97139.015 | F23: =LN(E23) -> 11.483898 | G23: 11.471398 | H23: =F23-G23 -> 0.012500854 | I23: =$J$14+$J$15*D23 -> 11.462293 | J23: =F23-I23 -> 0.021605035
D24: =D23+1 -> 1967 | E24: =HLOOKUP(D24,$E$1:$BQ$3,3,FALSE) -> 99481.697 | F24: =LN(E24) -> 11.507729 | G24: 11.505408 | H24: =F24-G24 -> 0.0023207962 | I24: =$J$14+$J$15*D24 -> 11.495764 | J24: =F24-I24 -> 0.01196481
D25: =D24+1 -> 1968 | E25: =HLOOKUP(D25,$E$1:$BQ$3,3,FALSE) -> 105342.35 | F25: =LN(E25) -> 11.564971 | G25: 11.538564 | H25: =F25-G25 -> 0.026407155 | I25: =$J$14+$J$15*D25 -> 11.529235 | J25: =F25-I25 -> 0.035735797
D26: =D25+1 -> 1969 | E26: =HLOOKUP(D26,$E$1:$BQ$3,3,FALSE) -> 105480.8 | F26: =LN(E26) -> 11.566284 | G26: 11.570958 | H26: =F26-G26 -> -0.0046737304 | I26: =$J$14+$J$15*D26 -> 11.562706 | J26: =F26-I26 -> 0.0035784236
D27: =D26+1 -> 1970 | E27: =HLOOKUP(D27,$E$1:$BQ$3,3,FALSE) -> 108842.78 | F27: =LN(E27) -> 11.59766 | G27: 11.602949 | H27: =F27-G27 -> -0.0052895608 | I27: =$J$14+$J$15*D27 -> 11.596177 | J27: =F27-I27 -> 0.0014831459
D28: =D27+1 -> 1971 | E28: =HLOOKUP(D28,$E$1:$BQ$3,3,FALSE) -> 109495.45 | F28: =LN(E28) -> 11.603638 | G28: 11.634849 | H28: =F28-G28 -> -0.031210806 | I28: =$J$14+$J$15*D28 -> 11.629647 | J28: =F28-I28 -> -0.026009085
D29: =D28+1 -> 1972 | E29: =HLOOKUP(D29,$E$1:$BQ$3,3,FALSE) -> 114957.68 | F29: =LN(E29) -> 11.652319 | G29: 11.666916 | H29: =F29-G29 -> -0.014596569 | I29: =$J$14+$J$15*D29 -> 11.663118 | J29: =F29-I29 -> -0.010798847
... D40: =D39+1 -> 1983 | E40: =HLOOKUP(D40,$E$1:$BQ$3,3,FALSE) -> 152640.7 | F40: =LN(E40) -> 11.935842 | G40: 11.934364 | H40: =F40-G40 -> 0.0014782486 | I40: =$J$14+$J$15*D40 -> 12.031297 | J40: =F40-I40 -> -0.095455005
D41: =D40+1 -> 1984 | E41: =HLOOKUP(D41,$E$1:$BQ$3,3,FALSE) -> 154702.81 | F41: =LN(E41) -> 11.949261 | G41: 11.936126 | H41: =F41-G41 -> 0.013134948
D42: =D41+1 -> 1985 | E42: =HLOOKUP(D42,$E$1:$BQ$3,3,FALSE) -> 154443.44 | F42: =LN(E42) -> 11.947583 | G42: 11.935283 | H42: =F42-G42 -> 0.012300323
D43: =D42+1 -> 1986 | E43: =HLOOKUP(D43,$E$1:$BQ$3,3,FALSE) -> 145386.04 | F43: =LN(E43) -> 11.887148 | G43: 11.933283 | H43: =F43-G43 -> -0.046135268
D44: =D43+1 -> 1987 | E44: =HLOOKUP(D44,$E$1:$BQ$3,3,FALSE) -> 145440.42 | F44: =LN(E44) -> 11.887522 | G44: 11.931699 | H44: =F44-G44 -> -0.044177111
D45: =D44+1 -> 1988 | E45: =HLOOKUP(D45,$E$1:$BQ$3,3,FALSE) -> 144332.72 | F45: =LN(E45) -> 11.879876 | G45: 11.931641 | H45: =F45-G45 -> -0.051764659
D46: =D45+1 -> 1989 | E46: =HLOOKUP(D46,$E$1:$BQ$3,3,FALSE) -> 146709.04 | F46: =LN(E46) -> 11.896207 | G46: 11.933779 | H46: =F46-G46 -> -0.037572299
D47: =D46+1 -> 1990 | E47: =HLOOKUP(D47,$E$1:$BQ$3,3,FALSE) -> 151478.63 | F47: =LN(E47) -> 11.9282 | G47: 11.938264 | H47: =F47-G47 -> -0.010063765
D48: =D47+1 -> 1991 | E48: =HLOOKUP(D48,$E$1:$BQ$3,3,FALSE) -> 154497.14 | F48: =LN(E48) -> 11.947931 | G48: 11.944871 | H48: =F48-G48 -> 0.0030600617
D49: =D48+1 -> 1992 | E49: =HLOOKUP(D49,$E$1:$BQ$3,3,FALSE) -> 157008.68 | F49: =LN(E49) -> 11.964056 | G49: 11.953276 | H49: =F49-G49 -> 0.010780717
D50: =D49+1 -> 1993 | E50: =HLOOKUP(D50,$E$1:$BQ$3,3,FALSE) -> 158545.4 | F50: =LN(E50) -> 11.973796 | G50: 11.963184 | H50: =F50-G50 -> 0.010612471
D51: =D50+1 -> 1994 | E51: =HLOOKUP(D51,$E$1:$BQ$3,3,FALSE) -> 162535.22 | F51: =LN(E51) -> 11.99865 | G51: 11.974409 | H51: =F51-G51 -> 0.024241418
D52: =D51+1 -> 1995 | E52: =HLOOKUP(D52,$E$1:$BQ$3,3,FALSE) -> 150230.5 | F52: =LN(E52) -> 11.919926 | G52: 11.98687 | H52: =F52-G52 -> -0.066943551
... D76: =D75+1 -> 2019 | E76: =HLOOKUP(D76,$E$1:$BQ$3,3,FALSE) -> 191485.05 | F76: =LN(E76) -> 12.162565 | G76: 12.172056 | H76: =F76-G76 -> -0.0094911844

Sheet M1
A1: Banco de México
A3: Agregados monetarios y activos financieros internos
A4: Agregados monetarios (metodología 2018)
A6: Fecha de consulta: 26/06/2025 08:51:08
A10: Título | B10: Agregados Monetarios, M1
A11: Periodo disponible | B11: Dic 2000 - Abr 2025
A12: Periodicidad | B12: Mensual
A13: Cifra | B13: Saldos
A14: Unidad | B14: Miles de Pesos
A15: Base
A16: Aviso
A17: Tipo de información | B17: Niveles
A18: Fecha | B18: SF311408 | F18: M1
A19: 36861 | B19: 5.7563476e+08 | E19: 36892 | F19: =AVERAGE(B20:B22) -> 5.1724154e+08
A20: 36892 | B20: 5.2483613e+08 | E20: 36982 | F20: =AVERAGE(B23:B25) -> 5.1927853e+08
A21: 36923 | B21: 5.1718661e+08 | E21: 37073 | F21: =AVERAGE(B26:B28) -> 5.5366736e+08
A22: 36951 | B22: 5.0970187e+08 | E22: 37165 | F22: =AVERAGE(B29:B31) -> 6.2268534e+08
A23: 36982 | B23: 5.1195243e+08 | E23: 37257 | F23: =AVERAGE(B32:B34) -> 6.345527e+08
A24: 37012 | B24: 5.1484546e+08 | E24: 37347 | F24: =AVERAGE(B35:B37) -> 6.387434e+08
A25: 37043 | B25: 5.3103769e+08 | E25: 37438 | F25: =AVERAGE(B38:B40) -> 6.5066789e+08
A26: 37073 | B26: 5.3559066e+08 | E26: 37530 | F26: =AVERAGE(B41:B43) -> 6.992638e+08
A27: 37104 | B27: 5.4663748e+08 | E27: 37622 | F27: =AVERAGE(B44:B46) -> 7.1382544e+08
A28: 37135 | B28: 5.7877395e+08 | E28: 37712 | F28: =AVERAGE(B47:B49) -> 7.1408971e+08
A29: 37165 | B29: 5.773955e+08 | E29: 37803 | F29: =AVERAGE(B50:B52) -> 7.2204542e+08
A30: 37196 | B30: 6.1019542e+08 | E30: 37895 | F30: =AVERAGE(B53:B55) -> 7.8481006e+08
A31: 37226 | B31: 6.804651e+08 | E31: 37987 | F31: =AVERAGE(B56:B58) -> 8.0442241e+08
A32: 37257 | B32: 6.3373584e+08 | E32: 38078 | F32: =AVERAGE(B59:B61) -> 8.2198621e+08
A33: 37288 | B33: 6.2735042e+08 | E33: 38169 | F33: =AVERAGE(B62:B64) -> 8.292136e+08
A34: 37316 | B34: 6.4257182e+08 | E34: 38261 | F34: =AVERAGE(B65:B67) -> 8.8573326e+08
A35: 37347 | B35: 6.2981367e+08 | E35: 38353 | F35: =AVERAGE(B68:B70) -> 9.007962e+08
A36: 37377 | B36: 6.3283116e+08 | E36: 38443 | F36: =AVERAGE(B71:B73) -> 9.0428418e+08
A37: 37408 | B37: 6.5358538e+08 | E37: 38534 | F37: =AVERAGE(B74:B76) -> 9.2195332e+08
A38: 37438 | B38: 6.5035931e+08 | E38: 38626 | F38: =AVERAGE(B77:B79) -> 9.8839653e+08
A39: 37469 | B39: 6.4758324e+08 | E39: 38718 | F39: =AVERAGE(B80:B82) -> 1.0218158e+09
A40: 37500 | B40: 6.5406112e+08 | E40: 38808 | F40: =AVERAGE(B83:B85) -> 1.0623253e+09
A41: 37530 | B41: 6.5191183e+08 | E41: 38899 | F41: =AVERAGE(B86:B88) -> 1.0754597e+09
A42: 37561 | B42: 6.7963852e+08 | E42: 38991 | F42: =AVERAGE(B89:B91) -> 1.134491e+09
A43: 37591 | B43: 7.6624106e+08 | E43: 39083 | F43: =AVERAGE(B92:B94) -> 1.1402452e+09
A44: 37622 | B44: 7.1971702e+08 | E44: 39173 | F44: =AVERAGE(B95:B97) -> 1.1440156e+09
A45: 37653 | B45: 7.0737687e+08 | E45: 39264 | F45: =AVERAGE(B98:B100) -> 1.1780381e+09
...

Sheet GDP quarterly
A1: Banco de México
A3: Producción
A4: Producto Interno Bruto (Precios corrientes)
A6: Fecha de consulta: 26/06/2025 08:52:30
A10: Título | B10: Producto interno bruto, Producto interno bruto, a precios de mercado
A11: Periodo disponible | B11: Ene-Mar 1993 - Ene-Mar 2025
A12: Periodicidad | B12: Trimestral
A13: Cifra | B13: Flujos Constantes
A14: Unidad | B14: Millones de Pesos
A15: Base | B15: 2018
A16: Aviso
A17: Tipo de información | B17: Niveles
A18: Fecha | B18: SR17645
A19: 33970 | B19: 1591205.3
A20: 34060 | B20: 1645078.9
A21: 34151 | B21: 1662210
A22: 34243 | B22: 1708617.4
A23: 34335 | B23: 1750226.2
A24: 34425 | B24: 1864368.8
A25: 34516 | B25: 1878101.8
A26: 34608 | B26: 1981408.6
A27: 34700 | B27: 2126220.5
A28: 34790 | B28: 2356508.4
A29: 34881 | B29: 2504153
A30: 34973 | B30: 2774687.6
... A147: 45658 | B147: 34650228

Sheet Proxy for working capital
B1: Share M1 in firms | C1: =2/3 -> 0.66666667
E3: =AVERAGE(E5:E80) -> 0.080942316
B4: M1 (million pesos) | C4: GDP (million pesos) | D4: M1 in firms' hands | E4: proxy for working capital / GDP
A5: 36892 | B5: =VLOOKUP(A5,'M1'!$E$19:$F$115,2,FALSE)/1000 -> 517241.54 | C5: =VLOOKUP(A5,'GDP quarterly'!$A$19:$B$147,2,FALSE) -> 7320286.3 | D5: =B5*$C$1 -> 344827.69 | E5: =D5/C5 -> 0.047105766
A6: 36982 | B6: =VLOOKUP(A6,'M1'!$E$19:$F$115,2,FALSE)/1000 -> 519278.53 | C6: =VLOOKUP(A6,'GDP quarterly'!$A$19:$B$147,2,FALSE) -> 7459750.4 | D6: =B6*$C$1 -> 346185.68 | E6: =D6/C6 -> 0.04640714
A7: 37073 | B7: =VLOOKUP(A7,'M1'!$E$19:$F$115,2,FALSE)/1000 -> 553667.36 | C7: =VLOOKUP(A7,'GDP quarterly'!$A$19:$B$147,2,FALSE) -> 7502163.6 | D7: =B7*$C$1 -> 369111.58 | E7: =D7/C7 -> 0.049200683
A8: 37165 | B8: =VLOOKUP(A8,'M1'!$E$19:$F$115,2,FALSE)/1000 -> 622685.34 | C8: =VLOOKUP(A8,'GDP quarterly'!$A$19:$B$147,2,FALSE) -> 7466230.3 | D8: =B8*$C$1 -> 415123.56 | E8: =D8/C8 -> 0.055600155
A9: 37257 | B9: =VLOOKUP(A9,'M1'!$E$19:$F$115,2,FALSE)/1000 -> 634552.7 | C9: =VLOOKUP(A9,'GDP quarterly'!$A$19:$B$147,2,FALSE) -> 7309444.3 | D9: =B9*$C$1 -> 423035.13 | E9: =D9/C9 -> 0.057875143
A10: 37347 | B10: =VLOOKUP(A10,'M1'!$E$19:$F$115,2,FALSE)/1000 -> 638743.4 | C10: =VLOOKUP(A10,'GDP quarterly'!$A$19:$B$147,2,FALSE) -> 7941410 | D10: =B10*$C$1 -> 425828.94 | E10: =D10/C10 -> 0.053621326
A11: 37438 | B11: =VLOOKUP(A11,'M1'!$E$19:$F$115,2,FALSE)/1000 -> 650667.89 | C11: =VLOOKUP(A11,'GDP quarterly'!$A$19:$B$147,2,FALSE) -> 7971586 | D11: =B11*$C$1 -> 433778.59 | E11: =D11/C11 -> 0.054415595
A12: 37530 | B12: =VLOOKUP(A12,'M1'!$E$19:$F$115,2,FALSE)/1000 -> 699263.8 | C12: =VLOOKUP(A12,'GDP quarterly'!$A$19:$B$147,2,FALSE) -> 8088591.6 | D12: =B12*$C$1 -> 466175.87 | E12: =D12/C12 -> 0.05763375
A13: 37622 | B13: =VLOOKUP(A13,'M1'!$E$19:$F$115,2,FALSE)/1000 -> 713825.44 | C13: =VLOOKUP(A13,'GDP quarterly'!$A$19:$B$147,2,FALSE) -> 8093632 | D13: =B13*$C$1 -> 475883.62 | E13: =D13/C13 -> 0.05879729
A14: 37712 | B14: =VLOOKUP(A14,'M1'!$E$19:$F$115,2,FALSE)/1000 -> 714089.71 | C14: =VLOOKUP(A14,'GDP quarterly'!$A$19:$B$147,2,FALSE) -> 8253853.5 | D14: =B14*$C$1 -> 476059.81 | E14: =D14/C14 -> 0.057677279
A15: 37803 | B15: =VLOOKUP(A15,'M1'!$E$19:$F$115,2,FALSE)/1000 -> 722045.42 | C15: =VLOOKUP(A15,'GDP quarterly'!$A$19:$B$147,2,FALSE) -> 8210313.4 | D15: =B15*$C$1 -> 481363.62 | E15: =D15/C15 -> 0.05862914
A16: 37895 | B16: =VLOOKUP(A16,'M1'!$E$19:$F$115,2,FALSE)/1000 -> 784810.06 | C16: =VLOOKUP(A16,'GDP quarterly'!$A$19:$B$147,2,FALSE) -> 8480333.7 | D16: =B16*$C$1 -> 523206.7 | E16: =D16/C16 -> 0.061696476
... A101: 45658 | B101: =VLOOKUP(A101,'M1'!$E$19:$F$115,2,FALSE)/1000 -> 8035228.3 | C101: =VLOOKUP(A101,'GDP quarterly'!$A$19:$B$147,2,FALSE) -> 34650228 | D101: =B101*$C$1 -> 5356818.8 | E101: =D101/C101 -> 0.15459693

Sheet EMBI spreads
A1: Date | B1: Ticker | C1: Close | G1: av spread | H1: gdp cycle
A2: 12/31/1997 | B2: EMBPMEXD | C2: 402 | D2: =YEAR(A2) -> 1997 | E2: =MONTH(A2) -> 12 | F2: 1997 | G2: =AVERAGEIF($D$2:$D$7066,F2,$C$2:$C$7066)/100 -> 4.02 | H2: ='Trade balance'!F48 -> 0.1049022 | I2: =CORREL(G2:$G$24,H2:$H$24) -> 0.28533738 | K2: Average | L2: =AVERAGE(C2:C7066)/100 -> 2.924878
A3: 01/02/1998 | B3: EMBPMEXD | C3: 405 | D3: =YEAR(A3) -> 1998 | E3: =MONTH(A3) -> 1 | F3: =F2+1 -> 1998 | G3: =AVERAGEIF($D$2:$D$7066,F3,$C$2:$C$7066)/100 -> 5.775498 | H3: ='Trade balance'!F49 -> 3.001582 | I3: =CORREL(G3:$G$24,H3:$H$24) -> 0.29841837 | K3: Std | L3: =_xlfn.STDEV.P(C2:C7066)/100 -> 1.3573061
A4: 01/05/1998 | B4: EMBPMEXD | C4: 425 | D4: =YEAR(A4) -> 1998 | E4: =MONTH(A4) -> 1 | F4: =F3+1 -> 1999 | G4: =AVERAGEIF($D$2:$D$7066,F4,$C$2:$C$7066)/100 -> 6.0614786 | H4: ='Trade balance'!F50 -> 2.7417396 | I4: =CORREL(G4:$G$24,H4:$H$24) -> 0.19963159 | O4: diferencial de tasas
A5: 01/06/1998 | B5: EMBPMEXD | C5: 434 | D5: =YEAR(A5) -> 1998 | E5: =MONTH(A5) -> 1 | F5: =F4+1 -> 2000 | G5: =AVERAGEIF($D$2:$D$7066,F5,$C$2:$C$7066)/100 -> 3.7051984 | H5: ='Trade balance'!F51 -> 4.8559515 | I5: =CORREL(G5:$G$24,H5:$H$24) -> 0.026998496 | L5: =YEAR(N5) -> 1997 | M5: =MONTH(N5) -> 12 | N5: 35765 | O5: =AVERAGEIFS($C$2:$C$7066,$D$2:$D$7066,L5,$E$2:$E$7066,M5)/10000 -> 0.0402
A6: 01/07/1998 | B6: EMBPMEXD | C6: 419 | D6: =YEAR(A6) -> 1998 | E6: =MONTH(A6) -> 1 | F6: =F5+1 -> 2001 | G6: =AVERAGEIF($D$2:$D$7066,F6,$C$2:$C$7066)/100 -> 3.6644 | H6: ='Trade balance'!F52 -> 1.8267518 | I6: =CORREL(G6:$G$24,H6:$H$24) -> -0.21919493 | L6: =YEAR(N6) -> 1998 | M6: =MONTH(N6) -> 1 | N6: 35796 | O6: =AVERAGEIFS($C$2:$C$7066,$D$2:$D$7066,L6,$E$2:$E$7066,M6)/10000 -> 0.04238
A7: 01/08/1998 | B7: EMBPMEXD | C7: 427 | D7: =YEAR(A7) -> 1998 | E7: =MONTH(A7) -> 1 | F7: =F6+1 -> 2002 | G7: =AVERAGEIF($D$2:$D$7066,F7,$C$2:$C$7066)/100 -> 3.1865873 | H7: ='Trade balance'!F53 -> -0.79021562 | I7: =CORREL(G7:$G$24,H7:$H$24) -> -0.37800786 | L7: =YEAR(N7) -> 1998 | M7: =MONTH(N7) -> 2 | N7: 35827 | O7: =AVERAGEIFS($C$2:$C$7066,$D$2:$D$7066,L7,$E$2:$E$7066,M7)/10000 -> 0.038405263
A8: 01/09/1998 | B8: EMBPMEXD | C8: 444 | D8: =YEAR(A8) -> 1998 | E8: =MONTH(A8) -> 1 | F8: =F7+1 -> 2003 | G8: =AVERAGEIF($D$2:$D$7066,F8,$C$2:$C$7066)/100 -> 2.4419444 | H8: ='Trade balance'!F54 -> -1.8308931 | I8: =CORREL(G8:$G$24,H8:$H$24) -> -0.3797667 | L8: =YEAR(N8) -> 1998 | M8: =MONTH(N8) -> 3 | N8: 35855 | O8: =AVERAGEIFS($C$2:$C$7066,$D$2:$D$7066,L8,$E$2:$E$7066,M8)/10000 -> 0.037322727
A9: 01/12/1998 | B9: EMBPMEXD | C9: 444 | D9: =YEAR(A9) -> 1998 | E9: =MONTH(A9) -> 1 | F9: =F8+1 -> 2004 | G9: =AVERAGEIF($D$2:$D$7066,F9,$C$2:$C$7066)/100 -> 1.9002344 | H9: ='Trade balance'!F55 -> -0.41442742 | I9: =CORREL(G9:$G$24,H9:$H$24) -> -0.36796695 | L9: =YEAR(N9) -> 1998 | M9: =MONTH(N9) -> 4 | N9: 35886 | O9: =AVERAGEIFS($C$2:$C$7066,$D$2:$D$7066,L9,$E$2:$E$7066,M9)/10000 -> 0.038066667
A10: 01/13/1998 | B10: EMBPMEXD | C10: 437 | D10: =YEAR(A10) -> 1998 | E10: =MONTH(A10) -> 1 | F10: =F9+1 -> 2005 | G10: =AVERAGEIF($D$2:$D$7066,F10,$C$2:$C$7066)/100 -> 1.5560618 | H10: ='Trade balance'!F56 -> -0.28789542 | I10: =CORREL(G10:$G$24,H10:$H$24) -> -0.37630597 | L10: =YEAR(N10) -> 1998 | M10: =MONTH(N10) -> 5 | N10: 35916 | O10: =AVERAGEIFS($C$2:$C$7066,$D$2:$D$7066,L10,$E$2:$E$7066,M10)/10000 -> 0.041115
A11: 01/14/1998 | B11: EMBPMEXD | C11: 428 | D11: =YEAR(A11) -> 1998 | E11: =MONTH(A11) -> 1 | F11: =F10+1 -> 2006 | G11: =AVERAGEIF($D$2:$D$7066,F11,$C$2:$C$7066)/100 -> 1.2817969 | H11: ='Trade balance'!F57 -> 2.5567092 | I11: =CORREL(G11:$G$24,H11:$H$24) -> -0.40115193 | L11: =YEAR(N11) -> 1998 | M11: =MONTH(N11) -> 6 | N11: 35947 | O11: =AVERAGEIFS($C$2:$C$7066,$D$2:$D$7066,L11,$E$2:$E$7066,M11)/10000 -> 0.045572727
A12: 01/15/1998 | B12: EMBPMEXD | C12: 438 | D12: =YEAR(A12) -> 1998 | E12: =MONTH(A12) -> 1 | F12: =F11+1 -> 2007 | G12: =AVERAGEIF($D$2:$D$7066,F12,$C$2:$C$7066)/100 -> 1.25868 | H12: ='Trade balance'!F58 -> 2.877748 | I12: =CORREL(G12:$G$24,H12:$H$24) -> -0.30565169 | L12: =YEAR(N12) -> 1998 | M12: =MONTH(N12) -> 7 | N12: 35977 | O12: =AVERAGEIFS($C$2:$C$7066,$D$2:$D$7066,L12,$E$2:$E$7066,M12)/10000 -> 0.046154545
A13: 01/16/1998 | B13: EMBPMEXD | C13: 424 | D13: =YEAR(A13) -> 1998 | E13: =MONTH(A13) -> 1 | F13: =F12+1 -> 2008 | G13: =AVERAGEIF($D$2:$D$7066,F13,$C$2:$C$7066)/100 -> 2.5343825 | H13: ='Trade balance'!F59 -> 2.1654126 | I13: =CORREL(G13:$G$24,H13:$H$24) -> -0.11078636 | L13: =YEAR(N13) -> 1998 | M13: =MONTH(N13) -> 8 | N13: 36008 | O13: =AVERAGEIFS($C$2:$C$7066,$D$2:$D$7066,L13,$E$2:$E$7066,M13)/10000 -> 0.069228571
A14: 01/20/1998 | B14: EMBPMEXD | C14: 423 | D14: =YEAR(A14) -> 1998 | E14: =MONTH(A14) -> 1 | F14: =F13+1 -> 2009 | G14: =AVERAGEIF($D$2:$D$7066,F14,$C$2:$C$7066)/100 -> 3.0032411 | H14: ='Trade balance'!F60 -> -5.9611747 | I14: =CORREL(G14:$G$24,H14:$H$24) -> -0.15291535 | L14: =YEAR(N14) -> 1998 | M14: =MONTH(N14) -> 9 | N14: 36039 | O14: =AVERAGEIFS($C$2:$C$7066,$D$2:$D$7066,L14,$E$2:$E$7066,M14)/10000 -> 0.095042857
A15: 01/21/1998 | B15: EMBPMEXD | C15: 436 | D15: =YEAR(A15) -> 1998 | E15: =MONTH(A15) -> 1 | F15: =F14+1 -> 2010 | G15: =AVERAGEIF($D$2:$D$7066,F15,$C$2:$C$7066)/100 -> 1.8617763 | H15: ='Trade balance'!F61 -> -2.7862803 | I15: =CORREL(G15:$G$24,H15:$H$24) -> 0.29860301 | L15: =YEAR(N15) -> 1998 | M15: =MONTH(N15) -> 10 | N15: 36069 | O15: =AVERAGEIFS($C$2:$C$7066,$D$2:$D$7066,L15,$E$2:$E$7066,M15)/10000 -> 0.089561905
A16: 01/22/1998 | B16: EMBPMEXD | C16: 432 | D16: =YEAR(A16) -> 1998 | E16: =MONTH(A16) -> 1 | F16: =F15+1 -> 2011 | G16: =AVERAGEIF($D$2:$D$7066,F16,$C$2:$C$7066)/100 -> 1.8650485 | H16: ='Trade balance'!F62 -> -1.1489338 | I16: =CORREL(G16:$G$24,H16:$H$24) -> 0.10806808 | L16: =YEAR(N16) -> 1998 | M16: =MONTH(N16) -> 11 | N16: 36100 | O16: =AVERAGEIFS($C$2:$C$7066,$D$2:$D$7066,L16,$E$2:$E$7066,M16)/10000 -> 0.072794737
... A24: 02/03/1998 | B24: EMBPMEXD | C24: 385 | D24: =YEAR(A24) -> 1998 | E24: =MONTH(A24) -> 2 | F24: =F23+1 -> 2019 | G24: =AVERAGEIF($D$2:$D$7066,F24,$C$2:$C$7066)/100 -> 3.181954 | H24: ='Trade balance'!F70 -> -1.3905237 | I24: =CORREL(G24:$G$24,H24:$H$24) -> #DIV/0! | L24: =YEAR(N24) -> 1999 | M24: =MONTH(N24) -> 7 | N24: 36342 | O24: =AVERAGEIFS($C$2:$C$7066,$D$2:$D$7066,L24,$E$2:$E$7066,M24)/10000 -> 0.067
A25: 02/04/1998 | B25: EMBPMEXD | C25: 381 | D25: =YEAR(A25) -> 1998 | E25: =MONTH(A25) -> 2 | L25: =YEAR(N25) -> 1999 | M25: =MONTH(N25) -> 8 | N25: 36373 | O25: =AVERAGEIFS($C$2:$C$7066,$D$2:$D$7066,L25,$E$2:$E$7066,M25)/10000 -> 0.067877273
A26: 02/05/1998 | B26: EMBPMEXD | C26: 377 | D26: =YEAR(A26) -> 1998 | E26: =MONTH(A26) -> 2 | L26: =YEAR(N26) -> 1999 | M26: =MONTH(N26) -> 9 | N26: 36404 | O26: =AVERAGEIFS($C$2:$C$7066,$D$2:$D$7066,L26,$E$2:$E$7066,M26)/10000 -> 0.060377273
A27: 02/06/1998 | B27: EMBPMEXD | C27: 373 | D27: =YEAR(A27) -> 1998 | E27: =MONTH(A27) -> 2 | L27: =YEAR(N27) -> 1999 | M27: =MONTH(N27) -> 10 | N27: 36434 | O27: =AVERAGEIFS($C$2:$C$7066,$D$2:$D$7066,L27,$E$2:$E$7066,M27)/10000 -> 0.05558
A28: 02/09/1998 | B28: EMBPMEXD | C28: 370 | D28: =YEAR(A28) -> 1998 | E28: =MONTH(A28) -> 2 | L28: =YEAR(N28) -> 1999 | M28: =MONTH(N28) -> 11 | N28: 36465 | O28: =AVERAGEIFS($C$2:$C$7066,$D$2:$D$7066,L28,$E$2:$E$7066,M28)/10000 -> 0.047471429
A29: 02/10/1998 | B29: EMBPMEXD | C29: 374 | D29: =YEAR(A29) -> 1998 | E29: =MONTH(A29) -> 2 | L29: =YEAR(N29) -> 1999 | M29: =MONTH(N29) -> 12 | N29: 36495 | O29: =AVERAGEIFS($C$2:$C$7066,$D$2:$D$7066,L29,$E$2:$E$7066,M29)/10000 -> 0.038959091
A30: 02/11/1998 | B30: EMBPMEXD | C30: 378 | D30: =YEAR(A30) -> 1998 | E30: =MONTH(A30) -> 2 | L30: =YEAR(N30) -> 2000 | M30: =MONTH(N30) -> 1 | N30: 36526 | O30: =AVERAGEIFS($C$2:$C$7066,$D$2:$D$7066,L30,$E$2:$E$7066,M30)/10000 -> 0.039875
A31: 02/12/1998 | B31: EMBPMEXD | C31: 384 | D31: =YEAR(A31) -> 1998 | E31: =MONTH(A31) -> 2 | L31: =YEAR(N31) -> 2000 | M31: =MONTH(N31) -> 2 | N31: 36557 | O31: =AVERAGEIFS($C$2:$C$7066,$D$2:$D$7066,L31,$E$2:$E$7066,M31)/10000 -> 0.038045
A32: 02/13/1998 | B32: EMBPMEXD | C32: 387 | D32: =YEAR(A32) -> 1998 | E32: =MONTH(A32) -> 2 | L32: =YEAR(N32) -> 2000 | M32: =MONTH(N32) -> 3 | N32: 36586 | O32: =AVERAGEIFS($C$2:$C$7066,$D$2:$D$7066,L32,$E$2:$E$7066,M32)/10000 -> 0.032669565
A33: 02/17/1998 | B33: EMBPMEXD | C33: 395 | D33: =YEAR(A33) -> 1998 | E33: =MONTH(A33) -> 2 | L33: =YEAR(N33) -> 2000 | M33: =MONTH(N33) -> 4 | N33: 36617 | O33: =AVERAGEIFS($C$2:$C$7066,$D$2:$D$7066,L33,$E$2:$E$7066,M33)/10000 -> 0.040005263
A34: 02/18/1998 | B34: EMBPMEXD | C34: 392 | D34: =YEAR(A34) -> 1998 | E34: =MONTH(A34) -> 2 | L34: =YEAR(N34) -> 2000 | M34: =MONTH(N34) -> 5 | N34: 36647 | O34: =AVERAGEIFS($C$2:$C$7066,$D$2:$D$7066,L34,$E$2:$E$7066,M34)/10000 -> 0.042295455
A35: 02/19/1998 | B35: EMBPMEXD | C35: 398 | D35: =YEAR(A35) -> 1998 | E35: =MONTH(A35) -> 2 | L35: =YEAR(N35) -> 2000 | M35: =MONTH(N35) -> 6 | N35: 36678 | O35: =AVERAGEIFS($C$2:$C$7066,$D$2:$D$7066,L35,$E$2:$E$7066,M35)/10000 -> 0.040004545
A36: 02/20/1998 | B36: EMBPMEXD | C36: 395 | D36: =YEAR(A36) -> 1998 | E36: =MONTH(A36) -> 2 | L36: =YEAR(N36) -> 2000 | M36: =MONTH(N36) -> 7 | N36: 36708 | O36: =AVERAGEIFS($C$2:$C$7066,$D$2:$D$7066,L36,$E$2:$E$7066,M36)/10000 -> 0.03517
... A333: 04/22/1999 | B333: EMBPMEXD | C333: 538 | D333: =YEAR(A333) -> 1999 | E333: =MONTH(A333) -> 4 | L333: =YEAR(N333) -> 2025 | M333: =MONTH(N333) -> 4 | N333: 45748 | O333: =AVERAGEIFS($C$2:$C$7066,$D$2:$D$7066,L333,$E$2:$E$7066,M333)/10000 -> 0.035163636
A334: 04/23/1999 | B334: EMBPMEXD | C334: 550 | D334: =YEAR(A334) -> 1999 | E334: =MONTH(A334) -> 4
A335: 04/26/1999 | B335: EMBPMEXD | C335: 547 | D335: =YEAR(A335) -> 1999 | E335: =MONTH(A335) -> 4
A336: 04/27/1999 | B336: EMBPMEXD | C336: 549 | D336: =YEAR(A336) -> 1999 | E336: =MONTH(A336) -> 4
A337: 04/28/1999 | B337: EMBPMEXD | C337: 540 | D337: =YEAR(A337) -> 1999 | E337: =MONTH(A337) -> 4
A338: 04/29/1999 | B338: EMBPMEXD | C338: 549 | D338: =YEAR(A338) -> 1999 | E338: =MONTH(A338) -> 4
A339: 04/30/1999 | B339: EMBPMEXD | C339: 532 | D339: =YEAR(A339) -> 1999 | E339: =MONTH(A339) -> 4
A340: 05/03/1999 | B340: EMBPMEXD | C340: 523 | D340: =YEAR(A340) -> 1999 | E340: =MONTH(A340) -> 5
A341: 05/04/1999 | B341: EMBPMEXD | C341: 522 | D341: =YEAR(A341) -> 1999 | E341: =MONTH(A341) -> 5
A342: 05/05/1999 | B342: EMBPMEXD | C342: 543 | D342: =YEAR(A342) -> 1999 | E342: =MONTH(A342) -> 5
A343: 05/06/1999 | B343: EMBPMEXD | C343: 538 | D343: =YEAR(A343) -> 1999 | E343: =MONTH(A343) -> 5
...

Sheet DefaultDummys, ReinhartRogoff
A1: SOVEREIGN EXTERNAL DEBT: DEFAULT and RESTRUCTURINGS, 1800-2012--Does not include defaults on WWI debt to United States
B2: Year | C2: 1800 | D2: =C2+1 -> 1801 | E2: =D2+1 -> 1802 | F2: =E2+1 -> 1803 | G2: =F2+1 -> 1804 | H2: =G2+1 -> 1805 | I2: =H2+1 -> 1806 | J2: =I2+1 -> 1807 | K2: =J2+1 -> 1808 | ... Z2: =Y2+1 -> 1823 | AA2: 1824 | AB2: 1825 | AC2: 1826 | AD2: 1827 | AE2: 1828 | AF2: 1829 | AG2: 1830 | AH2: 1831 | AI2: 1832 | AJ2: 1833 | AK2: 1834 | AL2: 1835 | AM2: 1836 | AN2: 1837 | AO2: 1838 | AP2: 1839 | AQ2: 1840 | AR2: 1841 | AS2: 1842 | AT2: 1843 | AU2: 1844 | AV2: 1845 | AW2: 1846 | AX2: 1847 | AY2: 1848 | AZ2: 1849 | BA2: 1850 | BB2: 1851 | BC2: 1852 | BD2: 1853 | BE2: 1854 | BF2: 1855 | BG2: 1856 | BH2: 1857 | BI2: 1858 | BJ2: 1859 | BK2: 1860 | BL2: 1861 | BM2: 1862 | BN2: 1863 | BO2: 1864 | BP2: 1865 | BQ2: 1866 | BR2: 1867 | BS2: 1868 | BT2: 1869 | BU2: 1870 | BV2: 1871 | BW2: 1872 | BX2: 1873 | BY2: 1874 | BZ2: 1875 | CA2: 1876 | CB2: 1877 | CC2: 1878 | CD2: 1879 | CE2: 1880 | CF2: 1881 | CG2: 1882 | CH2: 1883 | CI2: 1884 | CJ2: 1885 | CK2: 1886 | CL2: 1887 | CM2: 1888 | CN2: 1889 | CO2: 1890 | CP2: 1891 | CQ2: 1892 | CR2: 1893 | CS2: 1894 | CT2: 1895 | CU2: 1896 | CV2: 1897 | CW2: 1898 | CX2: 1899 | CY2: 1900 | CZ2: 1901 | DA2: 1902 | DB2: 1903 | DC2: 1904 | DD2: 1905 | DE2: 1906 | DF2: 1907 | DG2: 1908 | DH2: 1909 | DI2: 1910 | DJ2: 1911 | DK2: 1912 | DL2: 1913 | DM2: 1914 | DN2: 1915 | DO2: 1916 | DP2: 1917 | DQ2: 1918 | DR2: 1919 | DS2: 1920 | DT2: 1921 | DU2: 1922 | DV2: 1923 | DW2: 1924 | DX2: 1925 | DY2: 1926 | DZ2: 1927 | EA2: 1928 | EB2: 1929 | EC2: 1930 | ED2: 1931 | EE2: 1932 | EF2: 1933 | EG2: 1934 | EH2: 1935 | EI2: 1936 | EJ2: 1937 | EK2: 1938 | EL2: 1939 | EM2: 1940 | EN2: 1941 | EO2: 1942 | EP2: 1943 | EQ2: 1944 | ER2: 1945 | ES2: 1946 | ET2: 1947 | EU2: 1948 | EV2: 1949 | EW2: 1950 | EX2: 1951 | EY2: 1952 | EZ2: 1953 | FA2: 1954 | FB2: 1955 | FC2: 1956 | FD2: 1957 | FE2: 1958 | FF2: 1959 | FG2: 1960 | FH2: 1961 | FI2: 1962 | FJ2: 1963 | FK2: 1964 | FL2: 1965 | FM2: 1966 | FN2: 1967 | FO2: 1968 | FP2: 1969 | FQ2: 1970 | FR2: 1971 | FS2: 1972 | FT2: 1973 | FU2: 1974 | FV2: 1975 | FW2: 1976 | FX2: 1977 | FY2: 1978 | FZ2: 1979 | GA2: 1980 | GB2: 1981 | GC2: 1982 | GD2: 1983 | GE2: 1984 | GF2: 1985 | GG2: 1986 | GH2: 1987 | GI2: 1988 | GJ2: 1989 | GK2: 1990 | GL2: 1991 | GM2: 1992 | GN2: 1993 | GO2: 1994 | GP2: 1995 | GQ2: 1996 | GR2: 1997 | GS2: 1998 | GT2: 1999 | GU2: 2000 | GV2: 2001 | GW2: 2002 | GX2: 2003 | GY2: 2004 | GZ2: 2005 | HA2: 2006 | HB2: 2007 | HC2: 2008 | HD2: 2009 | HE2: 2010 | HF2: 2011 | HG2: 2012 | HH2: 2013 | HI2: 2014 | HJ2: Year of | HK2: No of years | HL2: No of years in default | HM2: P(default) | HO2: Share of world GDP
B3: Issuer | HJ3: Independence | HK3: since independence or 1800 | HO3: as of 1913 | HP3: as of 1990 | HQ3: as of 2003
C4: 1 | D4: 1 | E4: 1 | F4: 1 | G4: 1 | H4: 1 | I4: 1 | J4: 1 | K4: 1 | L4: 1 | M4: 1 | N4: 1 | O4: 1 | P4: 1 | Q4: 1 | R4: 1 | S4: 1 | T4: 1 | U4: 1 | V4: 1 | W4: 1 | X4: 1 | Y4: 1 | Z4: 1 | AA4: 1 | AB4: 1 | AC4: 1 | AD4: 1 | AE4: 1 | AF4: 1 | AG4: 1 | AH4: 1 | AI4: 1 | AJ4: 1 | AK4: 1 | AL4: 1 | AM4: 1 | AN4: 1 | AO4: 1 | AP4: 1 | AQ4: 1 | AR4: 1 | AS4: 1 | AT4: 1 | AU4: 1 | AV4: 1 | AW4: 1 | AX4: 1 | AY4: 1 | AZ4: 1 | BA4: 1 | BB4: 1 | BC4: 1 | BD4: 1 | BE4: 1 | BF4: 1 | BG4: 1 | BH4: 1 | BI4: 1 | BJ4: 1 | BK4: 1 | BL4: 1 | BM4: 1 | BN4: 1 | BO4: 1 | BP4: 1 | BQ4: 1 | BR4: 1 | BS4: 1 | BT4: 1 | BU4: 1 | BV4: 1 | BW4: 1 | BX4: 1 | BY4: 1 | BZ4: 1 | CA4: 1 | CB4: 1 | CC4: 1 | CD4: 1 | CE4: 1 | CF4: 1 | CG4: 1 | CH4: 1 | CI4: 1 | CJ4: 1 | CK4: 1 | CL4: 1 | CM4: 1 | CN4: 1 | CO4: 1 | CP4: 1 | CQ4: 1 | CR4: 1 | CS4: 1 | CT4: 1 | CU4: 1 | CV4: 1 | CW4: 1 | CX4: 1 | CY4: 1 | CZ4: 1 | DA4: 1 | DB4: 1 | DC4: 1 | DD4: 1 | DE4: 1 | DF4: 1 | DG4: 1 | DH4: 1 | DI4: 1 | DJ4: 1 | DK4: 1 | DL4: 1 | DM4: 1 | DN4: 1 | DO4: 1 | DP4: 1 | DQ4: 1 | DR4: 1 | DS4: 1 | DT4: 1 | DU4: 1 | DV4: 1 | DW4: 1 | DX4: 1 | DY4: 1 | DZ4: 1 | EA4: 1 | EB4: 1 | EC4: 1 | ED4: 1 | EE4: 1 | EF4: 1 | EG4: 1 | EH4: 1 | EI4: 1 | EJ4: 1 | EK4: 1 | EL4: 1 | EM4: 1 | EN4: 1 | EO4: 1 | EP4: 1 | EQ4: 1 | ER4: 1 | ES4: 1 | ET4: 1 | EU4: 1 | EV4: 1 | EW4: 1 | EX4: 1 | EY4: 1 | EZ4: 1 | FA4: 1 | FB4: 1 | FC4: 1 | FD4: 1 | FE4: 1 | FF4: 1 | FG4: 1 | FH4: 1 | FI4: 1 | FJ4: 1 | FK4: 1 | FL4: 1 | FM4: 1 | FN4: 1 | FO4: 1 | FP4: 1 | FQ4: 1 | FR4: 1 | FS4: 1 | FT4: 1 | FU4: 1 | FV4: 1 | FW4: 1 | FX4: 1 | FY4: 1 | FZ4: 1 | GA4: 1 | GB4: 1 | GC4: 1 | GD4: 1 | GE4: 1 | GF4: 1 | GG4: 1 | GH4: 1 | GI4: 1 | GJ4: 1 | GK4: 1 | GL4: 1 | GM4: 1 | GN4: 1 | GO4: 1 | GP4: 1 | GQ4: 1 | GR4: 1 | GS4: 1 | GT4: 1 | GU4: 1 | GV4: 1 | GW4: 1 | GX4: 1 | GY4: 1 | GZ4: 1 | HA4: 1 | HB4: 1 | HC4: 1 | HD4: 1 | HE4: 1 | HF4: 1 | HG4: 1 | HH4: 1 | HI4: 1 | HK4: =SUM(C$4:HI$4) -> 215
A5: Africa | B5: Algeria | C5: 0 | D5: 0 | E5: 0 | F5: 0 | G5: 0 | H5: 0 | I5: 0 | J5: 0 | K5: 0 | L5: 0 | M5: 0 | N5: 0 | O5: 0 | P5: 0 | Q5: 0 | R5: 0 | S5: 0 | T5: 0 | U5: 0 | V5: 0 | W5: 0 | X5: 0 | Y5: 0 | Z5: 0 | AA5: 0 | AB5: 0 | AC5: 0 | AD5: 0 | AE5: 0 | AF5: 0 | AG5: 0 | AH5: 0 | AI5: 0 | AJ5: 0 | AK5: 0 | AL5: 0 | AM5: 0 | AN5: 0 | AO5: 0 | AP5: 0 | AQ5: 0 | AR5: 0 | AS5: 0 | AT5: 0 | AU5: 0 | AV5: 0 | AW5: 0 | AX5: 0 | AY5: 0 | AZ5: 0 | BA5: 0 | BB5: 0 | BC5: 0 | BD5: 0 | BE5: 0 | BF5: 0 | BG5: 0 | BH5: 0 | BI5: 0 | BJ5: 0 | BK5: 0 | BL5: 0 | BM5: 0 | BN5: 0 | BO5: 0 | BP5: 0 | BQ5: 0 | BR5: 0 | BS5: 0 | BT5: 0 | BU5: 0 | BV5: 0 | BW5: 0 | BX5: 0 | BY5: 0 | BZ5: 0 | CA5: 0 | CB5: 0 | CC5: 0 | CD5: 0 | CE5: 0 | CF5: 0 | CG5: 0 | CH5: 0 | CI5: 0 | CJ5: 0 | CK5: 0 | CL5: 0 | CM5: 0 | CN5: 0 | CO5: 0 | CP5: 0 | CQ5: 0 | CR5: 0 | CS5: 0 | CT5: 0 | CU5: 0 | CV5: 0 | CW5: 0 | CX5: 0 | CY5: 0 | CZ5: 0 | DA5: 0 | DB5: 0 | DC5: 0 | DD5: 0 | DE5: 0 | DF5: 0 | DG5: 0 | DH5: 0 | DI5: 0 | DJ5: 0 | DK5: 0 | DL5: 0 | DM5: 0 | DN5: 0 | DO5: 0 | DP5: 0 | DQ5: 0 | DR5: 0 | DS5: 0 | DT5: 0 | DU5: 0 | DV5: 0 | DW5: 0 | DX5: 0 | DY5: 0 | DZ5: 0 | EA5: 0 | EB5: 0 | EC5: 0 | ED5: 0 | EE5: 0 | EF5: 0 | EG5: 0 | EH5: 0 | EI5: 0 | EJ5: 0 | EK5: 0 | EL5: 0 | EM5: 0 | EN5: 0 | EO5: 0 | EP5: 0 | EQ5: 0 | ER5: 0 | ES5: 0 | ET5: 0 | EU5: 0 | EV5: 0 | EW5: 0 | EX5: 0 | EY5: 0 | EZ5: 0 | FA5: 0 | FB5: 0 | FC5: 0 | FD5: 0 | FE5: 0 | FF5: 0 | FG5: 0 | FH5: 0 | FI5: 0 | FJ5: 0 | FK5: 0 | FL5: 0 | FM5: 0 | FN5: 0 | FO5: 0 | FP5: 0 | FQ5: 0 | FR5: 0 | FS5: 0 | FT5: 0 | FU5: 0 | FV5: 0 | FW5: 0 | FX5: 0 | FY5: 0 | FZ5: 0 | GA5: 0 | GB5: 0 | GC5: 0 | GD5: 0 | GE5: 0 | GF5: 0 | GG5: 0 | GH5: 0 | GI5: 0 | GJ5: 0 | GK5: 0 | GL5: 1 | GM5: 1 | GN5: 1 | GO5: 1 | GP5: 1 | GQ5: 1 | GR5: 0 | GS5: 0 | GT5: 0 | GU5: 0 | GV5: 0 | GW5: 0 | GX5: 0 | GY5: 0 | GZ5: 0 | HA5: 0 | HB5: 0 | HC5: 0 | HD5: 0 | HE5: 0 | HF5: 0 | HG5: 0 | HH5: 0 | HI5: 0 | HJ5: 1962 | HK5: =SUM(FI$4:HI$4) -> 53 | HL5: =SUM(FI5:$HI5) -> 6 | HM5: =100*HL5/HK5 -> 11.320755 | HO5: 0.23 | HP5: 0.27 | HQ5: 0.24434716
B6: Angola | C6: 0 | D6: 0 | E6: 0 | F6: 0 | G6: 0 | H6: 0 | I6: 0 | J6: 0 | K6: 0 | L6: 0 | M6: 0 | N6: 0 | O6: 0 | P6: 0 | Q6: 0 | R6: 0 | S6: 0 | T6: 0 | U6: 0 | V6: 0 | W6: 0 | X6: 0 | Y6: 0 | Z6: 0 | AA6: 0 | AB6: 0 | AC6: 0 | AD6: 0 | AE6: 0 | AF6: 0 | AG6: 0 | AH6: 0 | AI6: 0 | AJ6: 0 | AK6: 0 | AL6: 0 | AM6: 0 | AN6: 0 | AO6: 0 | AP6: 0 | AQ6: 0 | AR6: 0 | AS6: 0 | AT6: 0 | AU6: 0 | AV6: 0 | AW6: 0 | AX6: 0 | AY6: 0 | AZ6: 0 | BA6: 0 | BB6: 0 | BC6: 0 | BD6: 0 | BE6: 0 | BF6: 0 | BG6: 0 | BH6: 0 | BI6: 0 | BJ6: 0 | BK6: 0 | BL6: 0 | BM6: 0 | BN6: 0 | BO6: 0 | BP6: 0 | BQ6: 0 | BR6: 0 | BS6: 0 | BT6: 0 | BU6: 0 | BV6: 0 | BW6: 0 | BX6: 0 | BY6: 0 | BZ6: 0 | CA6: 0 | CB6: 0 | CC6: 0 | CD6: 0 | CE6: 0 | CF6: 0 | CG6: 0 | CH6: 0 | CI6: 0 | CJ6: 0 | CK6: 0 | CL6: 0 | CM6: 0 | CN6: 0 | CO6: 0 | CP6: 0 | CQ6: 0 | CR6: 0 | CS6: 0 | CT6: 0 | CU6: 0 | CV6: 0 | CW6: 0 | CX6: 0 | CY6: 0 | CZ6: 0 | DA6: 0 | DB6: 0 | DC6: 0 | DD6: 0 | DE6: 0 | DF6: 0 | DG6: 0 | DH6: 0 | DI6: 0 | DJ6: 0 | DK6: 0 | DL6: 0 | DM6: 0 | DN6: 0 | DO6: 0 | DP6: 0 | DQ6: 0 | DR6: 0 | DS6: 0 | DT6: 0 | DU6: 0 | DV6: 0 | DW6: 0 | DX6: 0 | DY6: 0 | DZ6: 0 | EA6: 0 | EB6: 0 | EC6: 0 | ED6: 0 | EE6: 0 | EF6: 0 | EG6: 0 | EH6: 0 | EI6: 0 | EJ6: 0 | EK6: 0 | EL6: 0 | EM6: 0 | EN6: 0 | EO6: 0 | EP6: 0 | EQ6: 0 | ER6: 0 | ES6: 0 | ET6: 0 | EU6: 0 | EV6: 0 | EW6: 0 | EX6: 0 | EY6: 0 | EZ6: 0 | FA6: 0 | FB6: 0 | FC6: 0 | FD6: 0 | FE6: 0 | FF6: 0 | FG6: 0 | FH6: 0 | FI6: 0 | FJ6: 0 | FK6: 0 | FL6: 0 | FM6: 0 | FN6: 0 | FO6: 0 | FP6: 0 | FQ6: 0 | FR6: 0 | FS6: 0 | FT6: 0 | FU6: 0 | FV6: 0 | FW6: 0 | FX6: 0 | FY6: 0 | FZ6: 0 | GA6: 0 | GB6: 0 | GC6: 0 | GD6: 0 | GE6: 0 | GF6: 1 | GG6: 1 | GH6: 1 | GI6: 1 | GJ6: 1 | GK6: 1 | GL6: 1 | GM6: 1 | GN6: 1 | GO6: 1 | GP6: 1 | GQ6: 1 | GR6: 1 | GS6: 1 | GT6: 1 | GU6: 1 | GV6: 1 | GW6: 1 | GX6: 1 | GY6: 0 | GZ6: 0 | HA6: 0 | HB6: 0 | HC6: 0 | HD6: 0 | HE6: 0 | HF6: 0 | HG6: 0 | HH6: 0 | HI6: 0 | HJ6: 1975 | HK6: =SUM(FV$4:HI$4) -> 40 | HL6: =SUM(FV6:HI6) -> 19 | HM6: =100*HL6/HK6 -> 47.5 | HO6: 0 | HP6: 0.03 | HQ6: 0.023964524
B7: Central African Republic | C7: 0 | D7: 0 | E7: 0 | F7: 0 | G7: 0 | H7: 0 | I7: 0 | J7: 0 | K7: 0 | L7: 0 | M7: 0 | N7: 0 | O7: 0 | P7: 0 | Q7: 0 | R7: 0 | S7: 0 | T7: 0 | U7: 0 | V7: 0 | W7: 0 | X7: 0 | Y7: 0 | Z7: 0 | AA7: 0 | AB7: 0 | AC7: 0 | AD7: 0 | AE7: 0 | AF7: 0 | AG7: 0 | AH7: 0 | AI7: 0 | AJ7: 0 | AK7: 0 | AL7: 0 | AM7: 0 | AN7: 0 | AO7: 0 | AP7: 0 | AQ7: 0 | AR7: 0 | AS7: 0 | AT7: 0 | AU7: 0 | AV7: 0 | AW7: 0 | AX7: 0 | AY7: 0 | AZ7: 0 | BA7: 0 | BB7: 0 | BC7: 0 | BD7: 0 | BE7: 0 | BF7: 0 | BG7: 0 | BH7: 0 | BI7: 0 | BJ7: 0 | BK7: 0 | BL7: 0 | BM7: 0 | BN7: 0 | BO7: 0 | BP7: 0 | BQ7: 0 | BR7: 0 | BS7: 0 | BT7: 0 | BU7: 0 | BV7: 0 | BW7: 0 | BX7: 0 | BY7: 0 | BZ7: 0 | CA7: 0 | CB7: 0 | CC7: 0 | CD7: 0 | CE7: 0 | CF7: 0 | CG7: 0 | CH7: 0 | CI7: 0 | CJ7: 0 | CK7: 0 | CL7: 0 | CM7: 0 | CN7: 0 | CO7: 0 | CP7: 0 | CQ7: 0 | CR7: 0 | CS7: 0 | CT7: 0 | CU7: 0 | CV7: 0 | CW7: 0 | CX7: 0 | CY7: 0 | CZ7: 0 | DA7: 0 | DB7: 0 | DC7: 0 | DD7: 0 | DE7: 0 | DF7: 0 | DG7: 0 | DH7: 0 | DI7: 0 | DJ7: 0 | DK7: 0 | DL7: 0 | DM7: 0 | DN7: 0 | DO7: 0 | DP7: 0 | DQ7: 0 | DR7: 0 | DS7: 0 | DT7: 0 | DU7: 0 | DV7: 0 | DW7: 0 | DX7: 0 | DY7: 0 | DZ7: 0 | EA7: 0 | EB7: 0 | EC7: 0 | ED7: 0 | EE7: 0 | EF7: 0 | EG7: 0 | EH7: 0 | EI7: 0 | EJ7: 0 | EK7: 0 | EL7: 0 | EM7: 0 | EN7: 0 | EO7: 0 | EP7: 0 | EQ7: 0 | ER7: 0 | ES7: 0 | ET7: 0 | EU7: 0 | EV7: 0 | EW7: 0 | EX7: 0 | EY7: 0 | EZ7: 0 | FA7: 0 | FB7: 0 | FC7: 0 | FD7: 0 | FE7: 0 | FF7: 0 | FG7: 0 | FH7: 0 | FI7: 0 | FJ7: 0 | FK7: 0 | FL7: 0 | FM7: 0 | FN7: 0 | FO7: 0 | FP7: 0 | FQ7: 0 | FR7: 0 | FS7: 0 | FT7: 0 | FU7: 0 | FV7: 0 | FW7: 0 | FX7: 0 | FY7: 0 | FZ7: 0 | GA7: 0 | GB7: 1 | GC7: 0 | GD7: 1 | GE7: 1 | GF7: 1 | GG7: 1 | GH7: 1 | GI7: 1 | GJ7: 1 | GK7: 1 | GL7: 1 | GM7: 1 | GN7: 1 | GO7: 1 | GP7: 1 | GQ7: 1 | GR7: 1 | GS7: 1 | GT7: 1 | GU7: 1 | GV7: 1 | GW7: 1 | GX7: 1 | GY7: 1 | GZ7: 1 | HA7: 1 | HB7: 1 | HC7: 1 | HD7: 1 | HE7: 1 | HF7: 1 | HG7: 1 | HH7: 1 | HI7: 1 | HJ7: 1960 | HK7: =SUM(FG$4:HI$4) -> 55 | HL7: =SUM(FG7:HI7) -> 33 | HM7: =100*HL7/HK7 -> 60 | HO7: 0 | HP7: 0.01 | HQ7: 0.01 | HS7: Need to confirm it is ongoing
B8: Cote d'Ivoire | C8: 0 | D8: 0 | E8: 0 | F8: 0 | G8: 0 | H8: 0 | I8: 0 | J8: 0 | K8: 0 | L8: 0 | M8: 0 | N8: 0 | O8: 0 | P8: 0 | Q8: 0 | R8: 0 | S8: 0 | T8: 0 | U8: 0 | V8: 0 | W8: 0 | X8: 0 | Y8: 0 | Z8: 0 | AA8: 0 | AB8: 0 | AC8: 0 | AD8: 0 | AE8: 0 | AF8: 0 | AG8: 0 | AH8: 0 | AI8: 0 | AJ8: 0 | AK8: 0 | AL8: 0 | AM8: 0 | AN8: 0 | AO8: 0 | AP8: 0 | AQ8: 0 | AR8: 0 | AS8: 0 | AT8: 0 | AU8: 0 | AV8: 0 | AW8: 0 | AX8: 0 | AY8: 0 | AZ8: 0 | BA8: 0 | BB8: 0 | BC8: 0 | BD8: 0 | BE8: 0 | BF8: 0 | BG8: 0 | BH8: 0 | BI8: 0 | BJ8: 0 | BK8: 0 | BL8: 0 | BM8: 0 | BN8: 0 | BO8: 0 | BP8: 0 | BQ8: 0 | BR8: 0 | BS8: 0 | BT8: 0 | BU8: 0 | BV8: 0 | BW8: 0 | BX8: 0 | BY8: 0 | BZ8: 0 | CA8: 0 | CB8: 0 | CC8: 0 | CD8: 0 | CE8: 0 | CF8: 0 | CG8: 0 | CH8: 0 | CI8: 0 | CJ8: 0 | CK8: 0 | CL8: 0 | CM8: 0 | CN8: 0 | CO8: 0 | CP8: 0 | CQ8: 0 | CR8: 0 | CS8: 0 | CT8: 0 | CU8: 0 | CV8: 0 | CW8: 0 | CX8: 0 | CY8: 0 | CZ8: 0 | DA8: 0 | DB8: 0 | DC8: 0 | DD8: 0 | DE8: 0 | DF8: 0 | DG8: 0 | DH8: 0 | DI8: 0 | DJ8: 0 | DK8: 0 | DL8: 0 | DM8: 0 | DN8: 0 | DO8: 0 | DP8: 0 | DQ8: 0 | DR8: 0 | DS8: 0 | DT8: 0 | DU8: 0 | DV8: 0 | DW8: 0 | DX8: 0 | DY8: 0 | DZ8: 0 | EA8: 0 | EB8: 0 | EC8: 0 | ED8: 0 | EE8: 0 | EF8: 0 | EG8: 0 | EH8: 0 | EI8: 0 | EJ8: 0 | EK8: 0 | EL8: 0 | EM8: 0 | EN8: 0 | EO8: 0 | EP8: 0 | EQ8: 0 | ER8: 0 | ES8: 0 | ET8: 0 | EU8: 0 | EV8: 0 | EW8: 0 | EX8: 0 | EY8: 0 | EZ8: 0 | FA8: 0 | FB8: 0 | FC8: 0 | FD8: 0 | FE8: 0 | FF8: 0 | FG8: 0 | FH8: 0 | FI8: 0 | FJ8: 0 | FK8: 0 | FL8: 0 | FM8: 0 | FN8: 0 | FO8: 0 | FP8: 0 | FQ8: 0 | FR8: 0 | FS8: 0 | FT8: 0 | FU8: 0 | FV8: 0 | FW8: 0 | FX8: 0 | FY8: 0 | FZ8: 0 | GA8: 0 | GB8: 0 | GC8: 0 | GD8: 1 | GE8: 1 | GF8: 1 | GG8: 1 | GH8: 1 | GI8: 1 | GJ8: 1 | GK8: 1 | GL8: 1 | GM8: 1 | GN8: 1 | GO8: 1 | GP8: 1 | GQ8: 1 | GR8: 1 | GS8: 1 | GT8: 0 | GU8: 1 | GV8: 1 | GW8: 1 | GX8: 1 | GY8: 1 | GZ8: 1 | HA8: 1 | HB8: 1 | HC8: 1 | HD8: 1 | HE8: 1 | HF8: 0 | HG8: 0 | HH8: 0 | HI8: 0 | HJ8: 1960 | HK8: =SUM(FG$4:HI$4) -> 55 | HL8: =SUM(FG8:HI8) -> 27 | HM8: =100*HL8/HK8 -> 49.090909 | HO8: 0 | HP8: 0.06 | HQ8: 0.05 | HS8: Need to check beyond 2010-Moody's documents 2011 default
B9: Egypt | C9: 0 | D9: 0 | E9: 0 | F9: 0 | G9: 0 | H9: 0 | I9: 0 | J9: 0 | K9: 0 | L9: 0 | M9: 0 | N9: 0 | O9: 0 | P9: 0 | Q9: 0 | R9: 0 | S9: 0 | T9: 0 | U9: 0 | V9: 0 | W9: 0 | X9: 0 | Y9: 0 | Z9: 0 | AA9: 0 | AB9: 0 | AC9: 0 | AD9: 0 | AE9: 0 | AF9: 0 | AG9: 0 | AH9: 0 | AI9: 0 | AJ9: 0 | AK9: 0 | AL9: 0 | AM9: 0 | AN9: 0 | AO9: 0 | AP9: 0 | AQ9: 0 | AR9: 0 | AS9: 0 | AT9: 0 | AU9: 0 | AV9: 0 | AW9: 0 | AX9: 0 | AY9: 0 | AZ9: 0 | BA9: 0 | BB9: 0 | BC9: 0 | BD9: 0 | BE9: 0 | BF9: 0 | BG9: 0 | BH9: 0 | BI9: 0 | BJ9: 0 | BK9: 0 | BL9: 0 | BM9: 0 | BN9: 0 | BO9: 0 | BP9: 0 | BQ9: 0 | BR9: 0 | BS9: 0 | BT9: 0 | BU9: 0 | BV9: 0 | BW9: 0 | BX9: 0 | BY9: 0 | BZ9: 0 | CA9: 1 | CB9: 1 | CC9: 1 | CD9: 1 | CE9: 1 | CF9: 0 | CG9: 0 | CH9: 0 | CI9: 0 | CJ9: 0 | CK9: 0 | CL9: 0 | CM9: 0 | CN9: 0 | CO9: 0 | CP9: 0 | CQ9: 0 | CR9: 0 | CS9: 0 | CT9: 0 | CU9: 0 | CV9: 0 | CW9: 0 | CX9: 0 | CY9: 0 | CZ9: 0 | DA9: 0 | DB9: 0 | DC9: 0 | DD9: 0 | DE9: 0 | DF9: 0 | DG9: 0 | DH9: 0 | DI9: 0 | DJ9: 0 | DK9: 0 | DL9: 0 | DM9: 0 | DN9: 0 | DO9: 0 | DP9: 0 | DQ9: 0 | DR9: 0 | DS9: 0 | DT9: 0 | DU9: 0 | DV9: 0 | DW9: 0 | DX9: 0 | DY9: 0 | DZ9: 0 | EA9: 0 | EB9: 0 | EC9: 0 | ED9: 0 | EE9: 0 | EF9: 0 | EG9: 0 | EH9: 0 | EI9: 0 | EJ9: 0 | EK9: 0 | EL9: 0 | EM9: 0 | EN9: 0 | EO9: 0 | EP9: 0 | EQ9: 0 | ER9: 0 | ES9: 0 | ET9: 0 | EU9: 0 | EV9: 0 | EW9: 0 | EX9: 0 | EY9: 0 | EZ9: 0 | FA9: 0 | FB9: 0 | FC9: 0 | FD9: 0 | FE9: 0 | FF9: 0 | FG9: 0 | FH9: 0 | FI9: 0 | FJ9: 0 | FK9: 0 | FL9: 0 | FM9: 0 | FN9: 0 | FO9: 0 | FP9: 0 | FQ9: 0 | FR9: 0 | FS9: 0 | FT9: 0 | FU9: 0 | FV9: 0 | FW9: 0 | FX9: 0 | FY9: 0 | FZ9: 0 | GA9: 0 | GB9: 0 | GC9: 0 | GD9: 0 | GE9: 1 | GF9: 0 | GG9: 0 | GH9: 0 | GI9: 0 | GJ9: 0 | GK9: 0 | GL9: 0 | GM9: 0 | GN9: 0 | GO9: 0 | GP9: 0 | GQ9: 0 | GR9: 0 | GS9: 0 | GT9: 0 | GU9: 0 | GV9: 0 | GW9: 0 | GX9: 0 | GY9: 0 | GZ9: 0 | HA9: 0 | HB9: 0 | HC9: 0 | HD9: 0 | HE9: 0 | HF9: 0 | HG9: 0 | HH9: 0 | HI9: 0 | HJ9: 1831 | HK9: =SUM(AH$4:HI$4) -> 184 | HL9: =SUM(C9:HI9) -> 6 | HM9: =100*HL9/HK9 -> 3.2608696 | HO9: 0.4 | HP9: 0.53 | HQ9: 0.56
B10: Kenya | C10: 0 | D10: 0 | E10: 0 | F10: 0 | G10: 0 | H10: 0 | I10: 0 | J10: 0 | K10: 0 | L10: 0 | M10: 0 | N10: 0 | O10: 0 | P10: 0 | Q10: 0 | R10: 0 | S10: 0 | T10: 0 | U10: 0 | V10: 0 | W10: 0 | X10: 0 | Y10: 0 | Z10: 0 | AA10: 0 | AB10: 0 | AC10: 0 | AD10: 0 | AE10: 0 | AF10: 0 | AG10: 0 | AH10: 0 | AI10: 0 | AJ10: 0 | AK10: 0 | AL10: 0 | AM10: 0 | AN10: 0 | AO10: 0 | AP10: 0 | AQ10: 0 | AR10: 0 | AS10: 0 | AT10: 0 | AU10: 0 | AV10: 0 | AW10: 0 | AX10: 0 | AY10: 0 | AZ10: 0 | BA10: 0 | BB10: 0 | BC10: 0 | BD10: 0 | BE10: 0 | BF10: 0 | BG10: 0 | BH10: 0 | BI10: 0 | BJ10: 0 | BK10: 0 | BL10: 0 | BM10: 0 | BN10: 0 | BO10: 0 | BP10: 0 | BQ10: 0 | BR10: 0 | BS10: 0 | BT10: 0 | BU10: 0 | BV10: 0 | BW10: 0 | BX10: 0 | BY10: 0 | BZ10: 0 | CA10: 0 | CB10: 0 | CC10: 0 | CD10: 0 | CE10: 0 | CF10: 0 | CG10: 0 | CH10: 0 | CI10: 0 | CJ10: 0 | CK10: 0 | CL10: 0 | CM10: 0 | CN10: 0 | CO10: 0 | CP10: 0 | CQ10: 0 | CR10: 0 | CS10: 0 | CT10: 0 | CU10: 0 | CV10: 0 | CW10: 0 | CX10: 0 | CY10: 0 | CZ10: 0 | DA10: 0 | DB10: 0 | DC10: 0 | DD10: 0 | DE10: 0 | DF10: 0 | DG10: 0 | DH10: 0 | DI10: 0 | DJ10: 0 | DK10: 0 | DL10: 0 | DM10: 0 | DN10: 0 | DO10: 0 | DP10: 0 | DQ10: 0 | DR10: 0 | DS10: 0 | DT10: 0 | DU10: 0 | DV10: 0 | DW10: 0 | DX10: 0 | DY10: 0 | DZ10: 0 | EA10: 0 | EB10: 0 | EC10: 0 | ED10: 0 | EE10: 0 | EF10: 0 | EG10: 0 | EH10: 0 | EI10: 0 | EJ10: 0 | EK10: 0 | EL10: 0 | EM10: 0 | EN10: 0 | EO10: 0 | EP10: 0 | EQ10: 0 | ER10: 0 | ES10: 0 | ET10: 0 | EU10: 0 | EV10: 0 | EW10: 0 | EX10: 0 | EY10: 0 | EZ10: 0 | FA10: 0 | FB10: 0 | FC10: 0 | FD10: 0 | FE10: 0 | FF10: 0 | FG10: 0 | FH10: 0 | FI10: 0 | FJ10: 0 | FK10: 0 | FL10: 0 | FM10: 0 | FN10: 0 | FO10: 0 | FP10: 0 | FQ10: 0 | FR10: 0 | FS10: 0 | FT10: 0 | FU10: 0 | FV10: 0 | FW10: 0 | FX10: 0 | FY10: 0 | FZ10: 0 | GA10: 0 | GB10: 0 | GC10: 0 | GD10: 0 | GE10: 0 | GF10: 0 | GG10: 0 | GH10: 0 | GI10: 0 | GJ10: 0 | GK10: 0 | GL10: 0 | GM10: 0 | GN10: 0 | GO10: 1 | GP10: 1 | GQ10: 1 | GR10: 1 | GS10: 1 | GT10: 0 | GU10: 1 | GV10: 0 | GW10: 0 | GX10: 0 | GY10: 0 | GZ10: 0 | HA10: 0 | HB10: 0 | HC10: 0 | HD10: 0 | HE10: 0 | HF10: 0 | HG10: 0 | HH10: 0 | HI10: 0 | HJ10: 1963 | HK10: =SUM(FJ$4:HI$4) -> 52 | HL10: =SUM(FJ10:HI10) -> 6 | HM10: =100*HL10/HK10 -> 11.538462 | HO10: 0 | HP10: 0.1 | HQ10: 0.08
B11: Morocco | C11: 0 | D11: 0 | E11: 0 | F11: 0 | G11: 0 | H11: 0 | I11: 0 | J11: 0 | K11: 0 | L11: 0 | M11: 0 | N11: 0 | O11: 0 | P11: 0 | Q11: 0 | R11: 0 | S11: 0 | T11: 0 | U11: 0 | V11: 0 | W11: 0 | X11: 0 | Y11: 0 | Z11: 0 | AA11: 0 | AB11: 0 | AC11: 0 | AD11: 0 | AE11: 0 | AF11: 0 | AG11: 0 | AH11: 0 | AI11: 0 | AJ11: 0 | AK11: 0 | AL11: 0 | AM11: 0 | AN11: 0 | AO11: 0 | AP11: 0 | AQ11: 0 | AR11: 0 | AS11: 0 | AT11: 0 | AU11: 0 | AV11: 0 | AW11: 0 | AX11: 0 | AY11: 0 | AZ11: 0 | BA11: 0 | BB11: 0 | BC11: 0 | BD11: 0 | BE11: 0 | BF11: 0 | BG11: 0 | BH11: 0 | BI11: 0 | BJ11: 0 | BK11: 0 | BL11: 0 | BM11: 0 | BN11: 0 | BO11: 0 | BP11: 0 | BQ11: 0 | BR11: 0 | BS11: 0 | BT11: 0 | BU11: 0 | BV11: 0 | BW11: 0 | BX11: 0 | BY11: 0 | BZ11: 0 | CA11: 0 | CB11: 0 | CC11: 0 | CD11: 0 | CE11: 0 | CF11: 0 | CG11: 0 | CH11: 0 | CI11: 0 | CJ11: 0 | CK11: 0 | CL11: 0 | CM11: 0 | CN11: 0 | CO11: 0 | CP11: 0 | CQ11: 0 | CR11: 0 | CS11: 0 | CT11: 0 | CU11: 0 | CV11: 0 | CW11: 0 | CX11: 0 | CY11: 0 | CZ11: 0 | DA11: 0 | DB11: 1 | DC11: 1 | DD11: 0 | DE11: 0 | DF11: 0 | DG11: 0 | DH11: 0 | DI11: 0 | DJ11: 0 | DK11: 0 | DL11: 0 | DM11: 0 | DN11: 0 | DO11: 0 | DP11: 0 | DQ11: 0 | DR11: 0 | DS11: 0 | DT11: 0 | DU11: 0 | DV11: 0 | DW11: 0 | DX11: 0 | DY11: 0 | DZ11: 0 | EA11: 0 | EB11: 0 | EC11: 0 | ED11: 0 | EE11: 0 | EF11: 0 | EG11: 0 | EH11: 0 | EI11: 0 | EJ11: 0 | EK11: 0 | EL11: 0 | EM11: 0 | EN11: 0 | EO11: 0 | EP11: 0 | EQ11: 0 | ER11: 0 | ES11: 0 | ET11: 0 | EU11: 0 | EV11: 0 | EW11: 0 | EX11: 0 | EY11: 0 | EZ11: 0 | FA11: 0 | FB11: 0 | FC11: 0 | FD11: 0 | FE11: 0 | FF11: 0 | FG11: 0 | FH11: 0 | FI11: 0 | FJ11: 0 | FK11: 0 | FL11: 0 | FM11: 0 | FN11: 0 | FO11: 0 | FP11: 0 | FQ11: 0 | FR11: 0 | FS11: 0 | FT11: 0 | FU11: 0 | FV11: 0 | FW11: 0 | FX11: 0 | FY11: 0 | FZ11: 0 | GA11: 0 | GB11: 0 | GC11: 0 | GD11: 1 | GE11: 0 | GF11: 0 | GG11: 1 | GH11: 1 | GI11: 1 | GJ11: 1 | GK11: 1 | GL11: 0 | GM11: 0 | GN11: 0 | GO11: 0 | GP11: 0 | GQ11: 0 | GR11: 0 | GS11: 0 | GT11: 0 | GU11: 0 | GV11: 0 | GW11: 0 | GX11: 0 | GY11: 0 | GZ11: 0 | HA11: 0 | HB11: 0 | HC11: 0 | HD11: 0 | HE11: 0 | HF11: 0 | HG11: 0 | HH11: 0 | HI11: 0 | HJ11: 1956 | HK11: =SUM(FC$4:HI$4) -> 59 | HL11: =SUM(FC11:HI11) -> 6 | HM11: =100*HL11/HK11 -> 10.169492 | HO11: 0.13 | HP11: 0.24 | HQ11: 0.23 | HS11: Does not include 1903-1904 default
B12: Mauritius | C12: 0 | D12: 0 | E12: 0 | F12: 0 | G12: 0 | H12: 0 | I12: 0 | J12: 0 | K12: 0 | L12: 0 | M12: 0 | N12: 0 | O12: 0 | P12: 0 | Q12: 0 | R12: 0 | S12: 0 | T12: 0 | U12: 0 | V12: 0 | W12: 0 | X12: 0 | Y12: 0 | Z12: 0 | AA12: 0 | AB12: 0 | AC12: 0 | AD12: 0 | AE12: 0 | AF12: 0 | AG12: 0 | AH12: 0 | AI12: 0 | AJ12: 0 | AK12: 0 | AL12: 0 | AM12: 0 | AN12: 0 | AO12: 0 | AP12: 0 | AQ12: 0 | AR12: 0 | AS12: 0 | AT12: 0 | AU12: 0 | AV12: 0 | AW12: 0 | AX12: 0 | AY12: 0 | AZ12: 0 | BA12: 0 | BB12: 0 | BC12: 0 | BD12: 0 | BE12: 0 | BF12: 0 | BG12: 0 | BH12: 0 | BI12: 0 | BJ12: 0 | BK12: 0 | BL12: 0 | BM12: 0 | BN12: 0 | BO12: 0 | BP12: 0 | BQ12: 0 | BR12: 0 | BS12: 0 | BT12: 0 | BU12: 0 | BV12: 0 | BW12: 0 | BX12: 0 | BY12: 0 | BZ12: 0 | CA12: 0 | CB12: 0 | CC12: 0 | CD12: 0 | CE12: 0 | CF12: 0 | CG12: 0 | CH12: 0 | CI12: 0 | CJ12: 0 | CK12: 0 | CL12: 0 | CM12: 0 | CN12: 0 | CO12: 0 | CP12: 0 | CQ12: 0 | CR12: 0 | CS12: 0 | CT12: 0 | CU12: 0 | CV12: 0 | CW12: 0 | CX12: 0 | CY12: 0 | CZ12: 0 | DA12: 0 | DB12: 0 | DC12: 0 | DD12: 0 | DE12: 0 | DF12: 0 | DG12: 0 | DH12: 0 | DI12: 0 | DJ12: 0 | DK12: 0 | DL12: 0 | DM12: 0 | DN12: 0 | DO12: 0 | DP12: 0 | DQ12: 0 | DR12: 0 | DS12: 0 | DT12: 0 | DU12: 0 | DV12: 0 | DW12: 0 | DX12: 0 | DY12: 0 | DZ12: 0 | EA12: 0 | EB12: 0 | EC12: 0 | ED12: 0 | EE12: 0 | EF12: 0 | EG12: 0 | EH12: 0 | EI12: 0 | EJ12: 0 | EK12: 0 | EL12: 0 | EM12: 0 | EN12: 0 | EO12: 0 | EP12: 0 | EQ12: 0 | ER12: 0 | ES12: 0 | ET12: 0 | EU12: 0 | EV12: 0 | EW12: 0 | EX12: 0 | EY12: 0 | EZ12: 0 | FA12: 0 | FB12: 0 | FC12: 0 | FD12: 0 | FE12: 0 | FF12: 0 | FG12: 0 | FH12: 0 | FI12: 0 | FJ12: 0 | FK12: 0 | FL12: 0 | FM12: 0 | FN12: 0 | FO12: 0 | FP12: 0 | FQ12: 0 | FR12: 0 | FS12: 0 | FT12: 0 | FU12: 0 | FV12: 0 | FW12: 0 | FX12: 0 | FY12: 0 | FZ12: 0 | GA12: 0 | GB12: 0 | GC12: 0 | GD12: 0 | GE12: 0 | GF12: 0 | GG12: 0 | GH12: 0 | GI12: 0 | GJ12: 0 | GK12: 0 | GL12: 0 | GM12: 0 | GN12: 0 | GO12: 0 | GP12: 0 | GQ12: 0 | GR12: 0 | GS12: 0 | GT12: 0 | GU12: 0 | GV12: 0 | GW12: 0 | GX12: 0 | GY12: 0 | GZ12: 0 | HA12: 0 | HB12: 0 | HC12: 0 | HD12: 0 | HE12: 0 | HF12: 0 | HG12: 0 | HH12: 0 | HI12: 0 | HJ12: 1968 | HK12: =SUM(FO$4:HI$4) -> 47 | HL12: =SUM(FO12:HI12) -> 0 | HM12: =100*HL12/HK12 -> 0 | HO12: 0 | HP12: 0.03 | HQ12: 0.04
B13: Nigeria | C13: 0 | D13: 0 | E13: 0 | F13: 0 | G13: 0 | H13: 0 | I13: 0 | J13: 0 | K13: 0 | L13: 0 | M13: 0 | N13: 0 | O13: 0 | P13: 0 | Q13: 0 | R13: 0 | S13: 0 | T13: 0 | U13: 0 | V13: 0 | W13: 0 | X13: 0 | Y13: 0 | Z13: 0 | AA13: 0 | AB13: 0 | AC13: 0 | AD13: 0 | AE13: 0 | AF13: 0 | AG13: 0 | AH13: 0 | AI13: 0 | AJ13: 0 | AK13: 0 | AL13: 0 | AM13: 0 | AN13: 0 | AO13: 0 | AP13: 0 | AQ13: 0 | AR13: 0 | AS13: 0 | AT13: 0 | AU13: 0 | AV13: 0 | AW13: 0 | AX13: 0 | AY13: 0 | AZ13: 0 | BA13: 0 | BB13: 0 | BC13: 0 | BD13: 0 | BE13: 0 | BF13: 0 | BG13: 0 | BH13: 0 | BI13: 0 | BJ13: 0 | BK13: 0 | BL13: 0 | BM13: 0 | BN13: 0 | BO13: 0 | BP13: 0 | BQ13: 0 | BR13: 0 | BS13: 0 | BT13: 0 | BU13: 0 | BV13: 0 | BW13: 0 | BX13: 0 | BY13: 0 | BZ13: 0 | CA13: 0 | CB13: 0 | CC13: 0 | CD13: 0 | CE13: 0 | CF13: 0 | CG13: 0 | CH13: 0 | CI13: 0 | CJ13: 0 | CK13: 0 | CL13: 0 | CM13: 0 | CN13: 0 | CO13: 0 | CP13: 0 | CQ13: 0 | CR13: 0 | CS13: 0 | CT13: 0 | CU13: 0 | CV13: 0 | CW13: 0 | CX13: 0 | CY13: 0 | CZ13: 0 | DA13: 0 | DB13: 0 | DC13: 0 | DD13: 0 | DE13: 0 | DF13: 0 | DG13: 0 | DH13: 0 | DI13: 0 | DJ13: 0 | DK13: 0 | DL13: 0 | DM13: 0 | DN13: 0 | DO13: 0 | DP13: 0 | DQ13: 0 | DR13: 0 | DS13: 0 | DT13: 0 | DU13: 0 | DV13: 0 | DW13: 0 | DX13: 0 | DY13: 0 | DZ13: 0 | EA13: 0 | EB13: 0 | EC13: 0 | ED13: 0 | EE13: 0 | EF13: 0 | EG13: 0 | EH13: 0 | EI13: 0 | EJ13: 0 | EK13: 0 | EL13: 0 | EM13: 0 | EN13: 0 | EO13: 0 | EP13: 0 | EQ13: 0 | ER13: 0 | ES13: 0 | ET13: 0 | EU13: 0 | EV13: 0 | EW13: 0 | EX13: 0 | EY13: 0 | EZ13: 0 | FA13: 0 | FB13: 0 | FC13: 0 | FD13: 0 | FE13: 0 | FF13: 0 | FG13: 0 | FH13: 0 | FI13: 0 | FJ13: 0 | FK13: 0 | FL13: 0 | FM13: 0 | FN13: 0 | FO13: 0 | FP13: 0 | FQ13: 0 | FR13: 0 | FS13: 0 | FT13: 0 | FU13: 0 | FV13: 0 | FW13: 0 | FX13: 0 | FY13: 0 | FZ13: 0 | GA13: 0 | GB13: 0 | GC13: 0 | GD13: 0 | GE13: 0 | GF13: 0 | GG13: 0 | GH13: 1 | GI13: 1 | GJ13: 1 | GK13: 1 | GL13: 1 | GM13: 1 | GN13: 1 | GO13: 1 | GP13: 0 | GQ13: 0 | GR13: 0 | GS13: 0 | GT13: 0 | GU13: 0 | GV13: 0 | GW13: 0 | GX13: 0 | GY13: 1 | GZ13: 1 | HA13: 0 | HB13: 0 | HC13: 0 | HD13: 0 | HE13: 0 | HF13: 0 | HG13: 0 | HJ13: 1960 | HK13: =SUM(FG$4:HI$4) -> 55 | HL13: =SUM(FG13:HI13) -> 10 | HM13: =100*HL13/HK13 -> 18.181818 | HO13: 0 | HP13: 0.4 | HQ13: 0.41
B14: South Africa | C14: 0 | D14: 0 | E14: 0 | F14: 0 | G14: 0 | H14: 0 | I14: 0 | J14: 0 | K14: 0 | L14: 0 | M14: 0 | N14: 0 | O14: 0 | P14: 0 | Q14: 0 | R14: 0 | S14: 0 | T14: 0 | U14: 0 | V14: 0 | W14: 0 | X14: 0 | Y14: 0 | Z14: 0 | AA14: 0 | AB14: 0 | AC14: 0 | AD14: 0 | AE14: 0 | AF14: 0 | AG14: 0 | AH14: 0 | AI14: 0 | AJ14: 0 | AK14: 0 | AL14: 0 | AM14: 0 | AN14: 0 | AO14: 0 | AP14: 0 | AQ14: 0 | AR14: 0 | AS14: 0 | AT14: 0 | AU14: 0 | AV14: 0 | AW14: 0 | AX14: 0 | AY14: 0 | AZ14: 0 | BA14: 0 | BB14: 0 | BC14: 0 | BD14: 0 | BE14: 0 | BF14: 0 | BG14: 0 | BH14: 0 | BI14: 0 | BJ14: 0 | BK14: 0 | BL14: 0 | BM14: 0 | BN14: 0 | BO14: 0 | BP14: 0 | BQ14: 0 | BR14: 0 | BS14: 0 | BT14: 0 | BU14: 0 | BV14: 0 | BW14: 0 | BX14: 0 | BY14: 0 | BZ14: 0 | CA14: 0 | CB14: 0 | CC14: 0 | CD14: 0 | CE14: 0 | CF14: 0 | CG14: 0 | CH14: 0 | CI14: 0 | CJ14: 0 | CK14: 0 | CL14: 0 | CM14: 0 | CN14: 0 | CO14: 0 | CP14: 0 | CQ14: 0 | CR14: 0 | CS14: 0 | CT14: 0 | CU14: 0 | CV14: 0 | CW14: 0 | CX14: 0 | CY14: 0 | CZ14: 0 | DA14: 0 | DB14: 0 | DC14: 0 | DD14: 0 | DE14: 0 | DF14: 0 | DG14: 0 | DH14: 0 | DI14: 0 | DJ14: 0 | DK14: 0 | DL14: 0 | DM14: 0 | DN14: 0 | DO14: 0 | DP14: 0 | DQ14: 0 | DR14: 0 | DS14: 0 | DT14: 0 | DU14: 0 | DV14: 0 | DW14: 0 | DX14: 0 | DY14: 0 | DZ14: 0 | EA14: 0 | EB14: 0 | EC14: 0 | ED14: 0 | EE14: 0 | EF14: 0 | EG14: 0 | EH14: 0 | EI14: 0 | EJ14: 0 | EK14: 0 | EL14: 0 | EM14: 0 | EN14: 0 | EO14: 0 | EP14: 0 | EQ14: 0 | ER14: 0 | ES14: 0 | ET14: 0 | EU14: 0 | EV14: 0 | EW14: 0 | EX14: 0 | EY14: 0 | EZ14: 0 | FA14: 0 | FB14: 0 | FC14: 0 | FD14: 0 | FE14: 0 | FF14: 0 | FG14: 0 | FH14: 0 | FI14: 0 | FJ14: 0 | FK14: 0 | FL14: 0 | FM14: 0 | FN14: 0 | FO14: 0 | FP14: 0 | FQ14: 0 | FR14: 0 | FS14: 0 | FT14: 0 | FU14: 0 | FV14: 0 | FW14: 0 | FX14: 0 | FY14: 0 | FZ14: 0 | GA14: 0 | GB14: 0 | GC14: 0 | GD14: 0 | GE14: 0 | GF14: 1 | GG14: 1 | GH14: 1 | GI14: 0 | GJ14: 1 | GK14: 0 | GL14: 0 | GM14: 0 | GN14: 1 | GO14: 0 | GP14: 0 | GQ14: 0 | GR14: 0 | GS14: 0 | GT14: 0 | GU14: 0 | GV14: 0 | GW14: 0 | GX14: 0 | GY14: 0 | GZ14: 0 | HA14: 0 | HB14: 0 | HC14: 0 | HD14: 0 | HE14: 0 | HF14: 0 | HG14: 0 | HJ14: 1910 | HK14: =SUM(DI$4:HI$4) -> 105 | HL14: =SUM(DI14:HI14) -> 5 | HM14: =100*HL14/HK14 -> 4.7619048 | HO14: 0.36 | HP14: 0.54 | HQ14: 0.47
B15: Tunisia | C15: 0 | D15: 0 | E15: 0 | F15: 0 | G15: 0 | H15: 0 | I15: 0 | J15: 0 | K15: 0 | L15: 0 | M15: 0 | N15: 0 | O15: 0 | P15: 0 | Q15: 0 | R15: 0 | S15: 0 | T15: 0 | U15: 0 | V15: 0 | W15: 0 | X15: 0 | Y15: 0 | Z15: 0 | AA15: 0 | AB15: 0 | AC15: 0 | AD15: 0 | AE15: 0 | AF15: 0 | AG15: 0 | AH15: 0 | AI15: 0 | AJ15: 0 | AK15: 0 | AL15: 0 | AM15: 0 | AN15: 0 | AO15: 0 | AP15: 0 | AQ15: 0 | AR15: 0 | AS15: 0 | AT15: 0 | AU15: 0 | AV15: 0 | AW15: 0 | AX15: 0 | AY15: 0 | AZ15: 0 | BA15: 0 | BB15: 0 | BC15: 0 | BD15: 0 | BE15: 0 | BF15: 0 | BG15: 0 | BH15: 0 | BI15: 0 | BJ15: 0 | BK15: 0 | BL15: 0 | BM15: 0 | BN15: 0 | BO15: 0 | BP15: 0 | BQ15: 0 | BR15: 1 | BS15: 1 | BT15: 1 | BU15: 1 | BV15: 0 | BW15: 0 | BX15: 0 | BY15: 0 | BZ15: 0 | CA15: 0 | CB15: 0 | CC15: 0 | CD15: 0 | CE15: 0 | CF15: 0 | CG15: 0 | CH15: 0 | CI15: 0 | CJ15: 0 | CK15: 0 | CL15: 0 | CM15: 0 | CN15: 0 | CO15: 0 | CP15: 0 | CQ15: 0 | CR15: 0 | CS15: 0 | CT15: 0 | CU15: 0 | CV15: 0 | CW15: 0 | CX15: 0 | CY15: 0 | CZ15: 0 | DA15: 0 | DB15: 0 | DC15: 0 | DD15: 0 | DE15: 0 | DF15: 0 | DG15: 0 | DH15: 0 | DI15: 0 | DJ15: 0 | DK15: 0 | DL15: 0 | DM15: 0 | DN15: 0 | DO15: 0 | DP15: 0 | DQ15: 0 | DR15: 0 | DS15: 0 | DT15: 0 | DU15: 0 | DV15: 0 | DW15: 0 | DX15: 0 | DY15: 0 | DZ15: 0 | EA15: 0 | EB15: 0 | EC15: 0 | ED15: 0 | EE15: 0 | EF15: 0 | EG15: 0 | EH15: 0 | EI15: 0 | EJ15: 0 | EK15: 0 | EL15: 0 | EM15: 0 | EN15: 0 | EO15: 0 | EP15: 0 | EQ15: 0 | ER15: 0 | ES15: 0 | ET15: 0 | EU15: 0 | EV15: 0 | EW15: 0 | EX15: 0 | EY15: 0 | EZ15: 0 | FA15: 0 | FB15: 0 | FC15: 1 | FD15: 0 | FE15: 1 | FF15: 0 | FG15: 0 | FH15: 0 | FI15: 0 | FJ15: 1 | FK15: 0 | FL15: 0 | FM15: 0 | FN15: 0 | FO15: 0 | FP15: 0 | FQ15: 0 | FR15: 0 | FS15: 0 | FT15: 0 | FU15: 0 | FV15: 0 | FW15: 0 | FX15: 0 | FY15: 0 | FZ15: 1 | GA15: 1 | GB15: 1 | GC15: 1 | GD15: 0 | GE15: 0 | GF15: 0 | GG15: 0 | GH15: 0 | GI15: 0 | GJ15: 0 | GK15: 0 | GL15: 0 | GM15: 0 | GN15: 0 | GO15: 0 | GP15: 0 | GQ15: 0 | GR15: 0 | GS15: 0 | GT15: 0 | GU15: 0 | GV15: 0 | GW15: 0 | GX15: 0 | GY15: 0 | GZ15: 0 | HA15: 0 | HB15: 0 | HC15: 0 | HD15: 0 | HE15: 0 | HF15: 0 | HG15: 0 | HJ15: 1591/1957 | HK15: =SUM(C$4:HI$4) -> 215 | HL15: =SUM(C15:HI15) -> 11 | HM15: =100*HL15/HK15 -> 5.1162791 | HO15: 0.06 | HP15: 0.1 | HQ15: 0.12
B16: Zambia | C16: 0 | D16: 0 | E16: 0 | F16: 0 | G16: 0 | H16: 0 | I16: 0 | J16: 0 | K16: 0 | L16: 0 | M16: 0 | N16: 0 | O16: 0 | P16: 0 | Q16: 0 | R16: 0 | S16: 0 | T16: 0 | U16: 0 | V16: 0 | W16: 0 | X16: 0 | Y16: 0 | Z16: 0 | AA16: 0 | AB16: 0 | AC16: 0 | AD16: 0 | AE16: 0 | AF16: 0 | AG16: 0 | AH16: 0 | AI16: 0 | AJ16: 0 | AK16: 0 | AL16: 0 | AM16: 0 | AN16: 0 | AO16: 0 | AP16: 0 | AQ16: 0 | AR16: 0 | AS16: 0 | AT16: 0 | AU16: 0 | AV16: 0 | AW16: 0 | AX16: 0 | AY16: 0 | AZ16: 0 | BA16: 0 | BB16: 0 | BC16: 0 | BD16: 0 | BE16: 0 | BF16: 0 | BG16: 0 | BH16: 0 | BI16: 0 | BJ16: 0 | BK16: 0 | BL16: 0 | BM16: 0 | BN16: 0 | BO16: 0 | BP16: 0 | BQ16: 0 | BR16: 0 | BS16: 0 | BT16: 0 | BU16: 0 | BV16: 0 | BW16: 0 | BX16: 0 | BY16: 0 | BZ16: 0 | CA16: 0 | CB16: 0 | CC16: 0 | CD16: 0 | CE16: 0 | CF16: 0 | CG16: 0 | CH16: 0 | CI16: 0 | CJ16: 0 | CK16: 0 | CL16: 0 | CM16: 0 | CN16: 0 | CO16: 0 | CP16: 0 | CQ16: 0 | CR16: 0 | CS16: 0 | CT16: 0 | CU16: 0 | CV16: 0 | CW16: 0 | CX16: 0 | CY16: 0 | CZ16: 0 | DA16: 0 | DB16: 0 | DC16: 0 | DD16: 0 | DE16: 0 | DF16: 0 | DG16: 0 | DH16: 0 | DI16: 0 | DJ16: 0 | DK16: 0 | DL16: 0 | DM16: 0 | DN16: 0 | DO16: 0 | DP16: 0 | DQ16: 0 | DR16: 0 | DS16: 0 | DT16: 0 | DU16: 0 | DV16: 0 | DW16: 0 | DX16: 0 | DY16: 0 | DZ16: 0 | EA16: 0 | EB16: 0 | EC16: 0 | ED16: 0 | EE16: 0 | EF16: 0 | EG16: 0 | EH16: 0 | EI16: 0 | EJ16: 0 | EK16: 0 | EL16: 0 | EM16: 0 | EN16: 0 | EO16: 0 | EP16: 0 | EQ16: 0 | ER16: 0 | ES16: 0 | ET16: 0 | EU16: 0 | EV16: 0 | EW16: 0 | EX16: 0 | EY16: 0 | EZ16: 0 | FA16: 0 | FB16: 0 | FC16: 0 | FD16: 0 | FE16: 0 | FF16: 0 | FG16: 0 | FH16: 0 | FI16: 0 | FJ16: 0 | FK16: 0 | FL16: 0 | FM16: 0 | FN16: 0 | FO16: 0 | FP16: 0 | FQ16: 0 | FR16: 0 | FS16: 0 | FT16: 0 | FU16: 0 | FV16: 0 | FW16: 0 | FX16: 0 | FY16: 0 | FZ16: 0 | GA16: 0 | GB16: 0 | GC16: 0 | GD16: 1 | GE16: 1 | GF16: 1 | GG16: 1 | GH16: 1 | GI16: 1 | GJ16: 1 | GK16: 1 | GL16: 1 | GM16: 1 | GN16: 1 | GO16: 1 | GP16: 0 | GQ16: 0 | GR16: 0 | GS16: 0 | GT16: 0 | GU16: 0 | GV16: 0 | GW16: 0 | GX16: 0 | GY16: 0 | GZ16: 0 | HA16: 0 | HB16: 0 | HC16: 0 | HD16: 0 | HE16: 0 | HF16: 0 | HG16: 0 | HJ16: 1964 | HK16: =SUM(FK$4:HI$4) -> 51 | HL16: =SUM(FK16:HI16) -> 12 | HM16: =100*HL16/HK16 -> 23.529412 | HO16: 0 | HP16: 0.02 | HQ16: 0.02
B17: Zimbabwe | C17: 0 | D17: 0 | E17: 0 | F17: 0 | G17: 0 | H17: 0 | I17: 0 | J17: 0 | K17: 0 | L17: 0 | M17: 0 | N17: 0 | O17: 0 | P17: 0 | Q17: 0 | R17: 0 | S17: 0 | T17: 0 | U17: 0 | V17: 0 | W17: 0 | X17: 0 | Y17: 0 | Z17: 0 | AA17: 0 | AB17: 0 | AC17: 0 | AD17: 0 | AE17: 0 | AF17: 0 | AG17: 0 | AH17: 0 | AI17: 0 | AJ17: 0 | AK17: 0 | AL17: 0 | AM17: 0 | AN17: 0 | AO17: 0 | AP17: 0 | AQ17: 0 | AR17: 0 | AS17: 0 | AT17: 0 | AU17: 0 | AV17: 0 | AW17: 0 | AX17: 0 | AY17: 0 | AZ17: 0 | BA17: 0 | BB17: 0 | BC17: 0 | BD17: 0 | BE17: 0 | BF17: 0 | BG17: 0 | BH17: 0 | BI17: 0 | BJ17: 0 | BK17: 0 | BL17: 0 | BM17: 0 | BN17: 0 | BO17: 0 | BP17: 0 | BQ17: 0 | BR17: 0 | BS17: 0 | BT17: 0 | BU17: 0 | BV17: 0 | BW17: 0 | BX17: 0 | BY17: 0 | BZ17: 0 | CA17: 0 | CB17: 0 | CC17: 0 | CD17: 0 | CE17: 0 | CF17: 0 | CG17: 0 | CH17: 0 | CI17: 0 | CJ17: 0 | CK17: 0 | CL17: 0 | CM17: 0 | CN17: 0 | CO17: 0 | CP17: 0 | CQ17: 0 | CR17: 0 | CS17: 0 | CT17: 0 | CU17: 0 | CV17: 0 | CW17: 0 | CX17: 0 | CY17: 0 | CZ17: 0 | DA17: 0 | DB17: 0 | DC17: 0 | DD17: 0 | DE17: 0 | DF17: 0 | DG17: 0 | DH17: 0 | DI17: 0 | DJ17: 0 | DK17: 0 | DL17: 0 | DM17: 0 | DN17: 0 | DO17: 0 | DP17: 0 | DQ17: 0 | DR17: 0 | DS17: 0 | DT17: 0 | DU17: 0 | DV17: 0 | DW17: 0 | DX17: 0 | DY17: 0 | DZ17: 0 | EA17: 0 | EB17: 0 | EC17: 0 | ED17: 0 | EE17: 0 | EF17: 0 | EG17: 0 | EH17: 0 | EI17: 0 | EJ17: 0 | EK17: 0 | EL17: 0 | EM17: 0 | EN17: 0 | EO17: 0 | EP17: 0 | EQ17: 0 | ER17: 0 | ES17: 0 | ET17: 0 | EU17: 0 | EV17: 0 | EW17: 0 | EX17: 0 | EY17: 0 | EZ17: 0 | FA17: 0 | FB17: 0 | FC17: 0 | FD17: 0 | FE17: 0 | FF17: 0 | FG17: 0 | FH17: 0 | FI17: 0 | FJ17: 0 | FK17: 0 | FL17: 1 | FM17: 1 | FN17: 1 | FO17: 1 | FP17: 1 | FQ17: 1 | FR17: 1 | FS17: 1 | FT17: 1 | FU17: 1 | FV17: 1 | FW17: 1 | FX17: 1 | FY17: 1 | FZ17: 1 | GA17: 1 | GB17: 0 | GC17: 0 | GD17: 0 | GE17: 0 | GF17: 0 | GG17: 0 | GH17: 0 | GI17: 0 | GJ17: 0 | GK17: 0 | GL17: 0 | GM17: 0 | GN17: 0 | GO17: 0 | GP17: 0 | GQ17: 0 | GR17: 0 | GS17: 0 | GT17: 0 | GU17: 1 | GV17: 1 | GW17: 1 | GX17: 1 | GY17: 1 | GZ17: 1 | HA17: 1 | HB17: 1 | HC17: 1 | HD17: 1 | HE17: 1 | HF17: 1 | HG17: 1 | HJ17: 1965 | HK17: =SUM(FL4:HI$4) -> 50 | HL17: =SUM(FL17:HI17) -> 29 | HM17: =100*HL17/HK17 -> 58 | HO17: 0 | HP17: 0.05 | HQ17: 0.03 | HS17: Need to confirm it is ongoing
