Workbook

Sheet Domestic and imported
A1: Instituto Nacional de Estadística y Geografía (INEGI).
A2: Sistema de Cuentas Nacionales de México. Matriz de Insumo Producto simétrica, Base 2018
A3: Matriz simétrica de insumo producto. Industria por industria/ Economía total / Origen doméstico e importado/ Subsector SCIAN/ Millones de pesos a precios básicos
A5: Concepto | B5: UTPB - Utilización total a precios básicos | C5: DI - Demanda intermedia | CD5: DA - Demanda agregada
C6: Total | D6: 111 - Agricultura | E6: 112 - Cría y explotación de animales | F6: 113 - Aprovechamiento forestal | G6: 114 - Pesca, caza y captura | H6: 115 - Servicios relacionados con las actividades agropecuarias y forestales | I6: 211 - Extracción de petróleo y gas | J6: 212 - Minería de minerales metálicos y no metálicos, excepto petróleo y gas | K6: 213 - Servicios relacionados con la minería | L6: 221 - Generación, transmisión, distribución y comercialización de energía eléctrica, suministro de agua y de gas natural por ductos al consumidor final | M6: 236 - Edificación | N6: 237 - Construcción de obras de ingeniería civil | O6: 238 - Trabajos especializados para la construcción | P6: 311 - Industria alimentaria | Q6: 312 - Industria de las bebidas y del tabaco | R6: 313 - Fabricación de insumos textiles y acabado de textiles | S6: 314 - Fabricación de productos textiles, excepto prendas de vestir | T6: 315 - Fabricación de prendas de vestir | U6: 316 - Curtido y acabado de cuero y piel, y fabricación de productos de cuero, piel y materiales sucedáneos | V6: 321 - Industria de la madera | W6: 322 - Industria del papel | X6: 323 - Impresión e industrias conexas | Y6: 324 - Fabricación de productos derivados del petróleo y del carbón | Z6: 325 - Industria química | AA6: 326 - Industria del plástico y del hule | AB6: 327 - Fabricación de productos a base de minerales no metálicos | AC6: 331 - Industrias metálicas básicas | AD6: 332 - Fabricación de productos metálicos | AE6: 333 - Fabricación de maquinaria y equipo | AF6: 334 - Fabricación de equipo de computación, comunicación, medición y de otros equipos, componentes y accesorios electrónicos | AG6: 335 - Fabricación de accesorios, aparatos eléctricos y equipo de generación de energía eléctrica | AH6: 336 - Fabricación de equipo de transporte | AI6: 337 - Fabricación de muebles, colchones y persianas | AJ6: 339 - Otras industrias manufactureras | AK6: 431 - Comercio al por mayor de abarrotes, alimentos, bebidas, hielo y tabaco | AL6: 461 - Comercio al por menor de abarrotes, alimentos, bebidas, hielo y tabaco | AM6: 481 - Transporte aéreo | AN6: 482 - Transporte por ferrocarril | AO6: 483 - Transporte por agua | AP6: 484 - Autotransporte de carga | AQ6: 485 - Transporte terrestre de pasajeros, excepto por ferrocarril | AR6: 486 - Transporte por ductos | AS6: 487 - Transporte turístico | AT6: 488 - Servicios relacionados con el transporte | AU6: 491 - Servicios postales | AV6: 492 - Servicios de mensajería y paquetería | AW6: 493 - Servicios de almacenamiento | AX6: 511 - Edición de periódicos, revistas, libros, software y otros materiales, y edición de estas publicaciones integrada con la impresión | AY6: 512 - Industria fílmica y del video, e industria del sonido | AZ6: 515 - Radio y televisión | BA6: 517 - Telecomunicaciones | BB6: 518 - Procesamiento electrónico de información, hospedaje y otros servicios relacionados | BC6: 519 - Otros servicios de información | BD6: 521 - Banca central | BE6: 522 - Instituciones de intermediación crediticia y financiera no bursátil | BF6: 523 - Actividades bursátiles, cambiarias y de inversión financiera | BG6: 524 - Compañías de seguros, fianzas, y administración de fondos para el retiro | BH6: 531 - Servicios inmobiliarios | BI6: 532 - Servicios de alquiler de bienes muebles | BJ6: 533 - Servicios de alquiler de marcas registradas, patentes y franquicias | BK6: 541 - Servicios profesionales, científicos y técnicos | BL6: 551 - Corporativos | BM6: 561 - Servicios de apoyo a los negocios | BN6: 562 - Manejo de residuos y servicios de remediación | BO6: 611 - Servicios educativos | BP6: 621 - Servicios médicos de consulta externa y servicios relacionados | BQ6: 622 - Hospitales | BR6: 623 - Residencias de asistencia social y para el cuidado de la salud | BS6: 624 - Otros servicios de asistencia social | BT6: 711 - Servicios artísticos, culturales y deportivos, y otros servicios relacionados | BU6: 712 - Museos, sitios históricos, zoológicos y similares | BV6: 713 - Servicios de entretenimiento en instalaciones recreativas y otros servicios recreativos | BW6: 721 - Servicios de alojamiento temporal | BX6: 722 - Servicios de preparación de alimentos y bebidas | BY6: 811 - Servicios de reparación y mantenimiento | BZ6: 812 - Servicios personales | CA6: 813 - Asociaciones y organizaciones | CB6: 814 - Hogares con empleados domésticos | CC6: 931 - Actividades legislativas, gubernamentales y de impartición de justicia | CD6: Total | CE6: CP - Consumo Privado | CF6: CG - Consumo de gobierno | CG6: P.51b - Formación bruta de capital fijo | CH6: P.52 - Variación de existencias | CI6: a P.6 - Exportaciones de bienes y servicios | CJ6: b P.7 - Importaciones de bienes y servicios | CK6: YA0 - Discrepancia estadística
A7: 111 - Agricultura | B7: 682846.43 | C7: 490741.13 | D7: 17872.458 | E7: 58727.6 | F7: 176.569 | G7: 15.594 | H7: 314.236 | I7: 0 | J7: 0 | K7: 0 | L7: 0 | M7: 39.5 | N7: 1589.433 | O7: 9.078 | P7: 320433.4 | Q7: 26560.817 | R7: 17644.121 | S7: 1015.461 | T7: 618.101 | U7: 58.905 | V7: 426.575 | W7: 5.262 | X7: 0 | Y7: 0 | Z7: 1745.046 | AA7: 4243.552 | AB7: 18.296 | AC7: 0 | AD7: 0 | AE7: 0 | AF7: 0.014 | AG7: 941.667 | AH7: 0 | AI7: 0 | AJ7: 458.171 | AK7: 0 | AL7: 0.141 | AM7: 0 | AN7: 0 | AO7: 0 | AP7: 0 | AQ7: 0 | AR7: 0 | AS7: 0 | AT7: 0 | AU7: 0 | AV7: 0 | AW7: 0 | AX7: 0 | AY7: 0 | AZ7: 0.005 | BA7: 0 | BB7: 0 | BC7: 0.001 | BD7: 0 | BE7: 0 | BF7: 0 | BG7: 0 | BH7: 0.014 | BI7: 0 | BJ7: 0 | BK7: 1.544 | BL7: 0 | BM7: 1.944 | BN7: 0 | BO7: 2.75 | BP7: 0.101 | BQ7: 572.652 | BR7: 49.174 | BS7: 265.093 | BT7: 0 | BU7: 0 | BV7: 0.085 | BW7: 10430.279 | BX7: 26189.763 | BY7: 0.001 | BZ7: 13.112 | CA7: 251.128 | CB7: 0 | CC7: 49.495 | CD7: 192105.3 | CE7: 177570.47 | CF7: 401.578 | CG7: 15150.198 | CH7: 2313.924 | CI7: 203046.56 | CJ7: -206377.43
A8: 112 - Cría y explotación de animales | B8: 495469.19 | C8: 368925.73 | D8: 5038.302 | E8: 11934.088 | F8: 0 | G8: 0 | H8: 0 | I8: 0.008 | J8: 0.001 | K8: 0.012 | L8: 0.002 | M8: 618.977 | N8: 0.01 | O8: 0.011 | P8: 348273.86 | Q8: 3.347 | R8: 666.294 | S8: 0 | T8: 0.001 | U8: 148.227 | V8: 0 | W8: 0.001 | X8: 0.001 | Y8: 0 | Z8: 379.584 | AA8: 0.002 | AB8: 0 | AC8: 0.001 | AD8: 0.001 | AE8: 0.001 | AF8: 0.002 | AG8: 0.053 | AH8: 0.021 | AI8: 0.001 | AJ8: 184.944 | AK8: 0.029 | AL8: 0.048 | AM8: 0.001 | AN8: 0 | AO8: 0 | AP8: 0 | AQ8: 0.004 | AR8: 0 | AS8: 0 | AT8: 0.001 | AU8: 0 | AV8: 0 | AW8: 0.002 | AX8: 0 | AY8: 0.014 | AZ8: 0.113 | BA8: 0.015 | BB8: 0 | BC8: 0.037 | BD8: 0 | BE8: 0.011 | BF8: 0 | BG8: 0.002 | BH8: 0.395 | BI8: 0 | BJ8: 0 | BK8: 0.004 | BL8: 0.002 | BM8: 52.522 | BN8: 0 | BO8: 0.077 | BP8: 2.77 | BQ8: 287.688 | BR8: 21.023 | BS8: 29.419 | BT8: 0 | BU8: 0 | BV8: 2.306 | BW8: 0.002 | BX8: 1274.867 | BY8: 0.046 | BZ8: 3.154 | CA8: 0.001 | CB8: 0 | CC8: 3.418 | CD8: 126543.46 | CE8: 53881.036 | CF8: 3.35 | CG8: 64919.281 | CH8: 4327.278 | CI8: 11279.802 | CJ8: -7867.282
A9: 113 - Aprovechamiento forestal | B9: 28827.855 | C9: 25766.231 | D9: 0 | E9: 0 | F9: 1262.96 | G9: 0 | H9: 0.057 | I9: 0 | J9: 0.671 | K9: 0 | L9: 0 | M9: 0 | N9: 0 | O9: 0 | P9: 766.463 | Q9: 0 | R9: 0 | S9: 4.527 | T9: 0.483 | U9: 170.383 | V9: 15512.362 | W9: 1182.954 | X9: 0.253 | Y9: 0 | Z9: 4354.616 | AA9: 783.116 | AB9: 366.077 | AC9: 0 | AD9: 22.078 | AE9: 0 | AF9: 2.596 | AG9: 4.691 | AH9: 0 | AI9: 623.412 | AJ9: 708.424 | AK9: 0 | AL9: 0 | AM9: 0 | AN9: 0 | AO9: 0 | AP9: 0 | AQ9: 0 | AR9: 0 | AS9: 0 | AT9: 0 | AU9: 0 | AV9: 0 | AW9: 0 | AX9: 0 | AY9: 0 | AZ9: 0 | BA9: 0 | BB9: 0 | BC9: 0 | BD9: 0 | BE9: 0 | BF9: 0 | BG9: 0 | BH9: 0 | BI9: 0 | BJ9: 0 | BK9: 0.008 | BL9: 0 | BM9: 0 | BN9: 0 | BO9: 0.099 | BP9: 0 | BQ9: 0 | BR9: 0 | BS9: 0 | BT9: 0 | BU9: 0 | BV9: 0 | BW9: 0 | BX9: 0 | BY9: 0 | BZ9: 0 | CA9: 0 | CB9: 0 | CC9: 0.001 | CD9: 3061.624 | CE9: 3236.816 | CF9: 0 | CG9: 0 | CH9: 6.253 | CI9: 1368.362 | CJ9: -1549.807
A10: 114 - Pesca, caza y captura | B10: 22972.495 | C10: 6172.513 | D10: 0 | E10: 0.032 | F10: 0.017 | G10: 16.199 | H10: 0.007 | I10: 2.141 | J10: 0.348 | K10: 3.202 | L10: 0.376 | M10: 5.523 | N10: 2.317 | O10: 2.529 | P10: 4864.585 | Q10: 0.15 | R10: 0.06 | S10: 0.056 | T10: 0.177 | U10: 0.043 | V10: 0.05 | W10: 8.532 | X10: 0.125 | Y10: 0.016 | Z10: 0.452 | AA10: 0.338 | AB10: 0.174 | AC10: 0.234 | AD10: 0.313 | AE10: 0.286 | AF10: 0.636 | AG10: 0.152 | AH10: 4.497 | AI10: 0.136 | AJ10: 0.343 | AK10: 4.456 | AL10: 7.068 | AM10: 0.106 | AN10: 0.042 | AO10: 0.02 | AP10: 0.066 | AQ10: 0.624 | AR10: 0.009 | AS10: 0.003 | AT10: 0.207 | AU10: 0.004 | AV10: 0.021 | AW10: 0.246 | AX10: 0.03 | AY10: 0.476 | AZ10: 0.131 | BA10: 1.953 | BB10: 0.012 | BC10: 0.013 | BD10: 0.002 | BE10: 1.71 | BF10: 0.078 | BG10: 0.23 | BH10: 0.715 | BI10: 0.089 | BJ10: 0.002 | BK10: 0.76 | BL10: 0.266 | BM10: 0.749 | BN10: 0.014 | BO10: 1.699 | BP10: 1.636 | BQ10: 0.685 | BR10: 0.028 | BS10: 0.18 | BT10: 0.078 | BU10: 0.462 | BV10: 0.346 | BW10: 658.279 | BX10: 567.994 | BY10: 0.487 | BZ10: 0.605 | CA10: 0.244 | CB10: 0 | CC10: 5.642 | CD10: 16799.982 | CE10: 12461.6 | CF10: 0.002 | CG10: 23.382 | CH10: 0.324 | CI10: 4716.085 | CJ10: -401.411
A11: 115 - Servicios relacionados con las actividades agropecuarias y forestales | B11: 10393.96 | C11: 9546.667 | D11: 3859.953 | E11: 729.703 | F11: 77.339 | G11: 19.418 | H11: 0.261 | I11: 0.02 | J11: 0.003 | K11: 0.001 | L11: 0.005 | M11: 0.225 | N11: 0.021 | O11: 0.006 | P11: 4104.789 | Q11: 0.014 | R11: 527.495 | S11: 0.002 | T11: 224.951 | U11: 0.001 | V11: 0.002 | W11: 0.01 | X11: 0.003 | Y11: 0.015 | Z11: 0.075 | AA11: 0.018 | AB11: 0.011 | AC11: 0.022 | AD11: 0.015 | AE11: 0.015 | AF11: 0.022 | AG11: 0.012 | AH11: 0.158 | AI11: 0.004 | AJ11: 0.812 | AK11: 0.07 | AL11: 0.05 | AM11: 0.004 | AN11: 0.001 | AO11: 0 | AP11: 0.015 | AQ11: 0.008 | AR11: 0 | AS11: 0 | AT11: 0.002 | AU11: 0 | AV11: 0.001 | AW11: 0 | AX11: 0.039 | AY11: 0.024 | AZ11: 0.022 | BA11: 0.006 | BB11: 0 | BC11: 0 | BD11: 0.001 | BE11: 0.133 | BF11: 0.003 | BG11: 0.001 | BH11: 0.02 | BI11: 0.002 | BJ11: 0 | BK11: 0.035 | BL11: 0.001 | BM11: 0.022 | BN11: 0 | BO11: 0.094 | BP11: 0.019 | BQ11: 0.034 | BR11: 0 | BS11: 0 | BT11: 0 | BU11: 0.001 | BV11: 0.002 | BW11: 0.005 | BX11: 0.015 | BY11: 0.005 | BZ11: 0.001 | CA11: 0.046 | CB11: 0 | CC11: 0.584 | CD11: 847.293 | CE11: 828.859 | CF11: 0.324 | CG11: 25.881 | CH11: 0 | CI11: 0.417 | CJ11: -8.188
A12: 211 - Extracción de petróleo y gas | B12: 886533.21 | C12: 392468.64 | D12: 4.417 | E12: 8.057 | F12: 0.119 | G12: 0.218 | H12: 0.084 | I12: 3.627 | J12: 1.749 | K12: 0.902 | L12: 3.243 | M12: 35.283 | N12: 4.849 | O12: 2.696 | P12: 34.101 | Q12: 3.442 | R12: 0.853 | S12: 0.674 | T12: 1.433 | U12: 0.862 | V12: 1.051 | W12: 5.021 | X12: 1.354 | Y12: 280842.23 | Z12: 111324.16 | AA12: 8.337 | AB12: 5.258 | AC12: 12.184 | AD12: 7.65 | AE12: 8.607 | AF12: 12.086 | AG12: 6.419 | AH12: 68.119 | AI12: 2 | AJ12: 3.034 | AK12: 4.18 | AL12: 1.983 | AM12: 1.943 | AN12: 0.241 | AO12: 0.154 | AP12: 4.355 | AQ12: 3.194 | AR12: 0.128 | AS12: 0.019 | AT12: 1.531 | AU12: 0.004 | AV12: 0.295 | AW12: 0.183 | AX12: 0.066 | AY12: 0.155 | AZ12: 0.206 | BA12: 2.471 | BB12: 0.035 | BC12: 0.003 | BD12: 0.139 | BE12: 1.238 | BF12: 0.044 | BG12: 0.085 | BH12: 2.346 | BI12: 0.86 | BJ12: 0.005 | BK12: 2.018 | BL12: 0.281 | BM12: 3.719 | BN12: 0.195 | BO12: 1.624 | BP12: 2.412 | BQ12: 4.474 | BR12: 0.041 | BS12: 0.301 | BT12: 0.215 | BU12: 0.066 | BV12: 0.728 | BW12: 2.338 | BX12: 4.117 | BY12: 1.979 | BZ12: 0.697 | CA12: 0.5 | CB12: 0 | CC12: 2.948 | CD12: 494064.58 | CE12: 518.713 | CF12: 0 | CG12: 95.936 | CH12: 0.007 | CI12: 493451.49 | CJ12: -1.566
A13: 212 - Minería de minerales metálicos y no metálicos, excepto petróleo y gas | B13: 421712.98 | C13: 379330.25 | D13: 514.206 | E13: 228.398 | F13: 15.74 | G13: 14.302 | H13: 2.023 | I13: 744.668 | J13: 9820.326 | K13: 393.958 | L13: 17960.148 | M13: 26384.015 | N13: 14441.717 | O13: 5003.589 | P13: 855.418 | Q13: 810.236 | R13: 1.438 | S13: 2.062 | T13: 4.457 | U13: 2.428 | V13: 2.693 | W13: 178.189 | X13: 6.279 | Y13: 831.614 | Z13: 12783.309 | AA13: 172.719 | AB13: 64801.689 | AC13: 216543.26 | AD13: 1186.204 | AE13: 44.967 | AF13: 80.355 | AG13: 363.892 | AH13: 1296.414 | AI13: 4.911 | AJ13: 1083.44 | AK13: 181.167 | AL13: 183.483 | AM13: 10.614 | AN13: 29.597 | AO13: 1.292 | AP13: 191.286 | AQ13: 360.949 | AR13: 21.934 | AS13: 1.933 | AT13: 35.047 | AU13: 0.029 | AV13: 35.044 | AW13: 4.639 | AX13: 3.137 | AY13: 14.541 | AZ13: 20.841 | BA13: 161.696 | BB13: 1.317 | BC13: 0.51 | BD13: 0.033 | BE13: 34.154 | BF13: 2.559 | BG13: 5.306 | BH13: 191.759 | BI13: 15.063 | BJ13: 0.146 | BK13: 66.78 | BL13: 3.951 | BM13: 58.367 | BN13: 1.188 | BO13: 122.067 | BP13: 282.254 | BQ13: 44.294 | BR13: 2.521 | BS13: 12.726 | BT13: 2.199 | BU13: 2.162 | BV13: 22.104 | BW13: 47.834 | BX13: 85.546 | BY13: 2.721 | BZ13: 21.431 | CA13: 19.659 | CB13: 0 | CC13: 445.305 | CD13: 42382.735 | CE13: 20.854 | CF13: 6.359 | CG13: 827.651 | CH13: 2007.874 | CI13: 96352.216 | CJ13: -56832.219
A14: 213 - Servicios relacionados con la minería | B14: 152934.19 | C14: 3485.49 | D14: 0 | E14: 0.007 | F14: 0.023 | G14: 0.011 | H14: 0.005 | I14: 3103.645 | J14: 300.167 | K14: 43.922 | L14: 0.357 | M14: 7.182 | N14: 3.089 | O14: 3.256 | P14: 0.09 | Q14: 0.016 | R14: 0.007 | S14: 0.01 | T14: 0.029 | U14: 0.007 | V14: 0.014 | W14: 0.088 | X14: 0.052 | Y14: 0.009 | Z14: 0.159 | AA14: 0.095 | AB14: 0.065 | AC14: 0.29 | AD14: 0.107 | AE14: 0.149 | AF14: 0.655 | AG14: 0.083 | AH14: 4.18 | AI14: 0.02 | AJ14: 0.036 | AK14: 1.412 | AL14: 1.395 | AM14: 0.024 | AN14: 0.038 | AO14: 0.012 | AP14: 0.012 | AQ14: 0.012 | AR14: 0.001 | AS14: 0 | AT14: 0.044 | AU14: 0 | AV14: 0.002 | AW14: 0.077 | AX14: 0.08 | AY14: 0.093 | AZ14: 0.073 | BA14: 0.034 | BB14: 0.003 | BC14: 0.006 | BD14: 0.001 | BE14: 0.657 | BF14: 0.044 | BG14: 0.079 | BH14: 0.216 | BI14: 0.015 | BJ14: 0 | BK14: 0.229 | BL14: 0.004 | BM14: 0.137 | BN14: 0.005 | BO14: 1.821 | BP14: 1.643 | BQ14: 0.712 | BR14: 0.035 | BS14: 0.2 | BT14: 0.015 | BU14: 0.018 | BV14: 0.092 | BW14: 0.073 | BX14: 0.187 | BY14: 0.026 | BZ14: 0.253 | CA14: 0.296 | CB14: 0 | CC14: 7.589 | CD14: 149448.7 | CE14: 0.344 | CF14: 0.108 | CG14: 149457.75 | CH14: 5.448 | CI14: 0.172 | CJ14: -15.128
A15: 221 - Generación, transmisión, distribución y comercialización de energía eléctrica, suministro de agua y de gas natural por ductos al consumidor final | B15: 735834.91 | C15: 452314.98 | D15: 10662.788 | E15: 5367.402 | F15: 104.655 | G15: 95.854 | H15: 166.707 | I15: 3251.582 | J15: 13961.72 | K15: 8063.642 | L15: 11879.983 | M15: 2384.52 | N15: 3662.105 | O15: 1580.792 | P15: 24813.883 | Q15: 4633.368 | R15: 6509.542 | S15: 1293.516 | T15: 4445.198 | U15: 1535.169 | V15: 1303.674 | W15: 5676.826 | X15: 1241.857 | Y15: 10862.973 | Z15: 13216.343 | AA15: 12443.23 | AB15: 8288.997 | AC15: 27654.932 | AD15: 6632.865 | AE15: 8412.439 | AF15: 15284.712 | AG15: 3840.675 | AH15: 41314.297 | AI15: 994.714 | AJ15: 2212.189 | AK15: 16710.864 | AL15: 67306.094 | AM15: 111.287 | AN15: 91.433 | AO15: 158.185 | AP15: 648.511 | AQ15: 1736.577 | AR15: 356.624 | AS15: 18.625 | AT15: 1041.017 | AU15: 15.905 | AV15: 116.23 | AW15: 1875.245 | AX15: 152.147 | AY15: 624.321 | AZ15: 1002.064 | BA15: 5046.857 | BB15: 267.333 | BC15: 26.469 | BD15: 34.136 | BE15: 3838.424 | BF15: 159.821 | BG15: 1427.316 | BH15: 18606.157 | BI15: 593.581 | BJ15: 8.607 | BK15: 4049.08 | BL15: 498.581 | BM15: 5898.381 | BN15: 117.115 | BO15: 12262.046 | BP15: 3955.492 | BQ15: 4343.692 | BR15: 147.98 | BS15: 490.628 | BT15: 343.025 | BU15: 201.272 | BV15: 2170.007 | BW15: 5143.011 | BX15: 4891.001 | BY15: 1998.961 | BZ15: 2895.453 | CA15: 1189.82 | CB15: 0 | CC15: 15952.459 | CD15: 283519.93 | CE15: 286082.97 | CF15: 17.511 | CG15: 607.812 | CH15: 0 | CI15: 4309.228 | CJ15: -7497.594
A16: 236 - Edificación | B16: 2090312.5 | C16: 27894.678 | D16: 11.804 | E16: 18.427 | F16: 1.509 | G16: 8.028 | H16: 1.254 | I16: 469.005 | J16: 357.27 | K16: 392.401 | L16: 535.833 | M16: 16227.947 | N16: 1305.87 | O16: 603.379 | P16: 177.855 | Q16: 25.936 | R16: 5.169 | S16: 4.626 | T16: 17.453 | U16: 5.29 | V16: 9.231 | W16: 43.505 | X16: 36.164 | Y16: 17.994 | Z16: 530.864 | AA16: 93.667 | AB16: 55.756 | AC16: 99.246 | AD16: 92.228 | AE16: 56.062 | AF16: 84.815 | AG16: 33.142 | AH16: 1282.241 | AI16: 21.81 | AJ16: 14.597 | AK16: 312.253 | AL16: 536.637 | AM16: 6.026 | AN16: 2.858 | AO16: 1.185 | AP16: 7.329 | AQ16: 20.654 | AR16: 189.074 | AS16: 0.103 | AT16: 11.213 | AU16: 0.128 | AV16: 1.068 | AW16: 23.398 | AX16: 2.562 | AY16: 20.312 | AZ16: 15.211 | BA16: 62.074 | BB16: 0.629 | BC16: 1.621 | BD16: 0.226 | BE16: 63.836 | BF16: 9.354 | BG16: 130.34 | BH16: 184.421 | BI16: 11.611 | BJ16: 0.157 | BK16: 1223.022 | BL16: 7.531 | BM16: 788.521 | BN16: 4.363 | BO16: 210.95 | BP16: 207.379 | BQ16: 54.182 | BR16: 2.746 | BS16: 24.422 | BT16: 9.399 | BU16: 3.118 | BV16: 66.017 | BW16: 60.982 | BX16: 148.258 | BY16: 39.833 | BZ16: 145.289 | CA16: 42.48 | CB16: 0 | CC16: 601.528 | CD16: 2062417.8 | CE16: 4232.269 | CF16: 59.437 | CG16: 2059440.1 | CH16: 0 | CI16: 2496.817 | CJ16: -3810.847
A17: 237 - Construcción de obras de ingeniería civil | B17: 568177.3 | C17: 47150.251 | D17: 8.864 | E17: 13.494 | F17: 2.649 | G17: 8.083 | H17: 1.368 | I17: 601.377 | J17: 362.267 | K17: 598.186 | L17: 525.611 | M17: 2971.287 | N17: 33829.962 | O17: 747.835 | P17: 137.379 | Q17: 20.96 | R17: 3.68 | S17: 3.605 | T17: 14.361 | U17: 4.224 | V17: 8.207 | W17: 40.616 | X17: 34.768 | Y17: 14.029 | Z17: 498.637 | AA17: 84.586 | AB17: 51.268 | AC17: 91.346 | AD17: 84.886 | AE17: 53.559 | AF17: 106.769 | AG17: 30.888 | AH17: 1382.452 | AI17: 18.366 | AJ17: 12.127 | AK17: 305.383 | AL17: 470.106 | AM17: 4.353 | AN17: 4.373 | AO17: 1.482 | AP17: 4.14 | AQ17: 6.45 | AR17: 179.873 | AS17: 0.055 | AT17: 8.814 | AU17: 0.073 | AV17: 0.577 | AW17: 22.636 | AX17: 2.972 | AY17: 13.558 | AZ17: 13.204 | BA17: 21.577 | BB17: 0.524 | BC17: 1.332 | BD17: 0.128 | BE17: 57.875 | BF17: 10.091 | BG17: 124.886 | BH17: 169.207 | BI17: 9.827 | BJ17: 0.132 | BK17: 1162.491 | BL17: 2.001 | BM17: 179.863 | BN17: 4.101 | BO17: 281.05 | BP17: 246.132 | BQ17: 81.913 | BR17: 4.416 | BS17: 24.145 | BT17: 8.267 | BU17: 3.399 | BV17: 37.257 | BW17: 55.929 | BX17: 126.78 | BY17: 28.513 | BZ17: 126.842 | CA17: 55.404 | CB17: 0 | CC17: 920.424 | CD17: 521027.05 | CE17: 1420.363 | CF17: 21666.505 | CG17: 499458.2 | CH17: 0 | CI17: 2276.05 | CJ17: -3794.062
A18: 238 - Trabajos especializados para la construcción | B18: 304773.24 | C18: 286480.84 | D18: 7.902 | E18: 21.449 | F18: 1283.715 | G18: 0.934 | H18: 12.143 | I18: 166.796 | J18: 4902.724 | K18: 1171.886 | L18: 61.171 | M18: 183463.98 | N18: 69080.584 | O18: 1353.996 | P18: 923.183 | Q18: 30.297 | R18: 2.758 | S18: 13.277 | T18: 42.151 | U18: 10.907 | V18: 4.819 | W18: 22.677 | X18: 24.604 | Y18: 137.472 | Z18: 54.824 | AA18: 24.067 | AB18: 23.286 | AC18: 33.887 | AD18: 25.503 | AE18: 30.616 | AF18: 37.492 | AG18: 14.098 | AH18: 243.285 | AI18: 9.886 | AJ18: 14.926 | AK18: 1000.265 | AL18: 1039.373 | AM18: 82.198 | AN18: 5.24 | AO18: 15.224 | AP18: 36.805 | AQ18: 124.75 | AR18: 18.06 | AS18: 1.522 | AT18: 24.045 | AU18: 0.406 | AV18: 5.741 | AW18: 33.232 | AX18: 2.594 | AY18: 8.156 | AZ18: 6.445 | BA18: 44.175 | BB18: 0.309 | BC18: 3.456 | BD18: 0.241 | BE18: 1115.346 | BF18: 1.3 | BG18: 16.628 | BH18: 92.259 | BI18: 4.8 | BJ18: 0.038 | BK18: 460.884 | BL18: 2.827 | BM18: 57.237 | BN18: 1.197 | BO18: 4401.697 | BP18: 1793.046 | BQ18: 1206.99 | BR18: 1.598 | BS18: 69.878 | BT18: 28.532 | BU18: 346.099 | BV18: 132.569 | BW18: 34.204 | BX18: 167.866 | BY18: 115.228 | BZ18: 25.247 | CA18: 8.695 | CB18: 0 | CC18: 10693.138 | CD18: 18292.402 | CE18: 969.495 | CF18: 38.329 | CG18: 17107.016 | CH18: 3.474 | CI18: 350.898 | CJ18: -176.81
... A84: 931 - Actividades legislativas, gubernamentales y de impartición de justicia | B84: 1305939.3 | C84: 499.619 | D84: 0 | E84: 0 | F84: 0 | G84: 0 | H84: 0 | I84: 0 | J84: 0 | K84: 0 | L84: 0 | M84: 0 | N84: 0 | O84: 0 | P84: 0 | Q84: 0 | R84: 0 | S84: 0 | T84: 0 | U84: 0 | V84: 0 | W84: 0 | X84: 0 | Y84: 0 | Z84: 0 | AA84: 0 | AB84: 0 | AC84: 0 | AD84: 0 | AE84: 0 | AF84: 0 | AG84: 0 | AH84: 0 | AI84: 0 | AJ84: 0 | AK84: 0 | AL84: 0 | AM84: 0 | AN84: 0 | AO84: 0 | AP84: 0 | AQ84: 0 | AR84: 0 | AS84: 0 | AT84: 0 | AU84: 0 | AV84: 0 | AW84: 0 | AX84: 0 | AY84: 0 | AZ84: 0 | BA84: 0 | BB84: 0 | BC84: 0 | BD84: 0 | BE84: 41.317 | BF84: 21.136 | BG84: 437.166 | BH84: 0 | BI84: 0 | BJ84: 0 | BK84: 0 | BL84: 0 | BM84: 0 | BN84: 0 | BO84: 0 | BP84: 0 | BQ84: 0 | BR84: 0 | BS84: 0 | BT84: 0 | BU84: 0 | BV84: 0 | BW84: 0 | BX84: 0 | BY84: 0 | BZ84: 0 | CA84: 0 | CB84: 0 | CC84: 0 | CD84: 1305439.6 | CE84: 6950.097 | CF84: 1298489.5 | CG84: 0 | CH84: 0 | CI84: 0 | CJ84: 0
A85: UETONI - Usos de la ET de origen nacional e importado | B85: 41959242 | C85: 18773096 | D85: 165184.98 | E85: 252628.64 | F85: 6080.69 | G85: 13159.222 | H85: 4448.99 | I85: 262200.12 | J85: 152354.44 | K85: 89202.819 | L85: 256368.93 | M85: 1022404.9 | N85: 350571.31 | O85: 122622.35 | P85: 1472875.4 | Q85: 222513.51 | R85: 66073.974 | S85: 29825.38 | T85: 101845.91 | U85: 52640.034 | V85: 50610.722 | W85: 187234.88 | X85: 60822.838 | Y85: 760591.51 | Z85: 750152.16 | AA85: 396752.29 | AB85: 238615.78 | AC85: 621121.8 | AD85: 340880.57 | AE85: 391587.42 | AF85: 1506816.6 | AG85: 430844.01 | AH85: 2897708.3 | AI85: 82230.259 | AJ85: 320207.19 | AK85: 611251.64 | AL85: 640062.84 | AM85: 155945.98 | AN85: 29764.341 | AO85: 12624.89 | AP85: 378990.08 | AQ85: 269178.67 | AR85: 12967.682 | AS85: 2310.229 | AT85: 79153.882 | AU85: 985.45 | AV85: 24038.16 | AW85: 35245.084 | AX85: 16026.21 | AY85: 33439.718 | AZ85: 48831.756 | BA85: 189450.38 | BB85: 5140.289 | BC85: 1345.739 | BD85: 5106.945 | BE85: 262021.01 | BF85: 14522.533 | BG85: 204263.76 | BH85: 184790.35 | BI85: 32986.73 | BJ85: 395.335 | BK85: 148287.13 | BL85: 85720.451 | BM85: 224689.44 | BN85: 10737.968 | BO85: 132736.17 | BP85: 103246.55 | BQ85: 167213.05 | BR85: 1792.189 | BS85: 16994.985 | BT85: 14493.534 | BU85: 4990.034 | BV85: 42763.679 | BW85: 143973.39 | BX85: 188900.28 | BY85: 88604.201 | BZ85: 47532.467 | CA85: 26215.995 | CB85: 0 | CC85: 394186.37 | CD85: 23186147 | CE85: 15571569 | CF85: 2714421.7 | CG85: 5533104.9 | CH85: 103964.58 | CI85: 8933758.5 | CJ85: -9670671.8 | CK85: 0
A86: P.721 - Compras directas en el exterior por residentes | B86: 0 | CD86: 0 | CE86: 270999.24 | CF86: 11557.36 | CG86: 0 | CH86: 0 | CI86: 0 | CJ86: -282556.6
A87: P.621 - Compras directas en el mercado interno por no residentes | B87: 5.8207661e-11 | CD87: 5.8207661e-11 | CE87: -501182.33 | CF87: -4581.333 | CG87: 0 | CH87: 0 | CI87: 505763.67 | CJ87: 0
A88: P.621+P.721 - Compras netas de residentes y no residentes | B88: 5.8207661e-11 | CD88: 5.8207661e-11 | CE88: -230183.09 | CF88: 6976.027 | CG88: 0 | CH88: 0 | CI88: 505763.67 | CJ88: -282556.6 | CK88: 0
A89: UONI_T - Usos de origen nacional e importado (total) | B89: 41959242 | C89: 18773096 | D89: 165184.98 | E89: 252628.64 | F89: 6080.69 | G89: 13159.222 | H89: 4448.99 | I89: 262200.12 | J89: 152354.44 | K89: 89202.819 | L89: 256368.93 | M89: 1022404.9 | N89: 350571.31 | O89: 122622.35 | P89: 1472875.4 | Q89: 222513.51 | R89: 66073.974 | S89: 29825.38 | T89: 101845.91 | U89: 52640.034 | V89: 50610.722 | W89: 187234.88 | X89: 60822.838 | Y89: 760591.51 | Z89: 750152.16 | AA89: 396752.29 | AB89: 238615.78 | AC89: 621121.8 | AD89: 340880.57 | AE89: 391587.42 | AF89: 1506816.6 | AG89: 430844.01 | AH89: 2897708.3 | AI89: 82230.259 | AJ89: 320207.19 | AK89: 611251.64 | AL89: 640062.84 | AM89: 155945.98 | AN89: 29764.341 | AO89: 12624.89 | AP89: 378990.08 | AQ89: 269178.67 | AR89: 12967.682 | AS89: 2310.229 | AT89: 79153.882 | AU89: 985.45 | AV89: 24038.16 | AW89: 35245.084 | AX89: 16026.21 | AY89: 33439.718 | AZ89: 48831.756 | BA89: 189450.38 | BB89: 5140.289 | BC89: 1345.739 | BD89: 5106.945 | BE89: 262021.01 | BF89: 14522.533 | BG89: 204263.76 | BH89: 184790.35 | BI89: 32986.73 | BJ89: 395.335 | BK89: 148287.13 | BL89: 85720.451 | BM89: 224689.44 | BN89: 10737.968 | BO89: 132736.17 | BP89: 103246.55 | BQ89: 167213.05 | BR89: 1792.189 | BS89: 16994.985 | BT89: 14493.534 | BU89: 4990.034 | BV89: 42763.679 | BW89: 143973.39 | BX89: 188900.28 | BY89: 88604.201 | BZ89: 47532.467 | CA89: 26215.995 | CB89: 0 | CC89: 394186.37 | CD89: 23186147 | CE89: 15341386 | CF89: 2721397.8 | CG89: 5533104.9 | CH89: 103964.58 | CI89: 9439522.2 | CJ89: -9953228.4 | CK89: 0
A90: D.21 - Impuestos sobre los productos | B90: 1393818.8 | C90: 316020.91 | D90: 1306.898 | E90: 312.005 | F90: 56.495 | G90: 237.708 | H90: 31.071 | I90: 2795.361 | J90: 4291.201 | K90: 2013.14 | L90: 22558.955 | M90: 2982.864 | N90: 3570.361 | O90: 349.786 | P90: 6473.307 | Q90: 1480.321 | R90: 184.55 | S90: 95.783 | T90: 378.859 | U90: 164.241 | V90: 143.733 | W90: 1068.697 | X90: 421.91 | Y90: 74266.668 | Z90: 10021.326 | AA90: 1927.139 | AB90: 1713.18 | AC90: 2309.543 | AD90: 1292.634 | AE90: 560.99 | AF90: 834.198 | AG90: 668.494 | AH90: 5283.898 | AI90: 234.804 | AJ90: 310.735 | AK90: 14821.402 | AL90: 8958.179 | AM90: 9903.702 | AN90: 1145.789 | AO90: 567.669 | AP90: 12725.16 | AQ90: 9315.629 | AR90: 200.573 | AS90: 61.499 | AT90: 504.952 | AU90: 5.294 | AV90: 604.381 | AW90: 314.129 | AX90: 68.557 | AY90: 210.515 | AZ90: 517.018 | BA90: 1225.02 | BB90: 12.37 | BC90: 28.967 | BD90: 6.356 | BE90: 340.468 | BF90: 56.386 | BG90: 82.381 | BH90: 2043.191 | BI90: 281.85 | BJ90: 4.929 | BK90: 1896.396 | BL90: 1161.267 | BM90: 1411.321 | BN90: 62.232 | BO90: 8837.619 | BP90: 6752.046 | BQ90: 8396.388 | BR90: 28.166 | BS90: 747.391 | BT90: 531.37 | BU90: 269.617 | BV90: 581.602 | BW90: 7037.411 | BX90: 6332.317 | BY90: 183.456 | BZ90: 169.508 | CA90: 89.682 | CB90: 0 | CC90: 57185.905 | CD90: 1077797.9 | CE90: 1038457.4 | CF90: 0 | CG90: 39340.29 | CH90: 0 | CI90: 0.177
A91: D.31 - Subsidios a los productos | B91: 90793.994 | C91: 3519.875 | D91: 0 | E91: 4.544 | F91: 0.115 | G91: 27.098 | H91: 0.022 | I91: 2.87 | J91: 0.213 | K91: 0.205 | L91: 0.196 | M91: 1.533 | N91: 26.393 | O91: 0.143 | P91: 1.103 | Q91: 0.105 | R91: 0.024 | S91: 0.072 | T91: 0.155 | U91: 0.028 | V91: 0.04 | W91: 0.222 | X91: 0.582 | Y91: 0.053 | Z91: 0.52 | AA91: 0.266 | AB91: 0.301 | AC91: 0.469 | AD91: 0.29 | AE91: 0.382 | AF91: 0.47 | AG91: 0.135 | AH91: 1.453 | AI91: 0.092 | AJ91: 0.116 | AK91: 10.808 | AL91: 177.251 | AM91: 2.785 | AN91: 0.159 | AO91: 28.561 | AP91: 0.37 | AQ91: 0.167 | AR91: 0.44 | AS91: 2.835 | AT91: 0.248 | AU91: 54.938 | AV91: 0.064 | AW91: 0.292 | AX91: 0.132 | AY91: 0.38 | AZ91: 416.203 | BA91: 469.294 | BB91: 0.041 | BC91: 0.204 | BD91: 54.212 | BE91: 683.368 | BF91: 15.574 | BG91: 514.985 | BH91: 5.446 | BI91: 0.218 | BJ91: 0.005 | BK91: 16.094 | BL91: 5.975 | BM91: 19.596 | BN91: 0.134 | BO91: 106.133 | BP91: 17.676 | BQ91: 20.309 | BR91: 0.022 | BS91: 1.016 | BT91: 1.178 | BU91: 3.674 | BV91: 1.782 | BW91: 5.149 | BX91: 0.594 | BY91: 0.683 | BZ91: 1.946 | CA91: 2.289 | CB91: 0 | CC91: 806.435 | CD91: 87274.119 | CE91: 86940.416 | CF91: 0 | CG91: 333.703 | CH91: 0 | CI91: 0
A92: D.21-D.31 - Impuestos sobre los productos, netos | B92: 1303024.8 | C92: 312501.04 | D92: 1306.898 | E92: 307.461 | F92: 56.38 | G92: 210.61 | H92: 31.049 | I92: 2792.491 | J92: 4290.988 | K92: 2012.935 | L92: 22558.759 | M92: 2981.331 | N92: 3543.968 | O92: 349.643 | P92: 6472.204 | Q92: 1480.216 | R92: 184.526 | S92: 95.711 | T92: 378.704 | U92: 164.213 | V92: 143.693 | W92: 1068.475 | X92: 421.328 | Y92: 74266.615 | Z92: 10020.806 | AA92: 1926.873 | AB92: 1712.879 | AC92: 2309.074 | AD92: 1292.344 | AE92: 560.608 | AF92: 833.728 | AG92: 668.359 | AH92: 5282.445 | AI92: 234.712 | AJ92: 310.619 | AK92: 14810.594 | AL92: 8780.928 | AM92: 9900.917 | AN92: 1145.63 | AO92: 539.108 | AP92: 12724.79 | AQ92: 9315.462 | AR92: 200.133 | AS92: 58.664 | AT92: 504.704 | AU92: -49.644 | AV92: 604.317 | AW92: 313.837 | AX92: 68.425 | AY92: 210.135 | AZ92: 100.815 | BA92: 755.726 | BB92: 12.329 | BC92: 28.763 | BD92: -47.856 | BE92: -342.9 | BF92: 40.812 | BG92: -432.604 | BH92: 2037.745 | BI92: 281.632 | BJ92: 4.924 | BK92: 1880.302 | BL92: 1155.292 | BM92: 1391.725 | BN92: 62.098 | BO92: 8731.486 | BP92: 6734.37 | BQ92: 8376.079 | BR92: 28.144 | BS92: 746.375 | BT92: 530.192 | BU92: 265.943 | BV92: 579.82 | BW92: 7032.262 | BX92: 6331.723 | BY92: 182.773 | BZ92: 167.562 | CA92: 87.393 | CB92: 0 | CC92: 56379.47 | CD92: 990523.79 | CE92: 951517.03 | CF92: 0 | CG92: 39006.587 | CH92: 0 | CI92: 0.177 | CJ92: 0 | CK92: 0
A93: UONI_PC - Usos de origen nacional e importado (total a precios comprador) | B93: 43262267 | C93: 19085597 | D93: 166491.88 | E93: 252936.1 | F93: 6137.07 | G93: 13369.832 | H93: 4480.039 | I93: 264992.61 | J93: 156645.43 | K93: 91215.754 | L93: 278927.69 | M93: 1025386.2 | N93: 354115.28 | O93: 122971.99 | P93: 1479347.6 | Q93: 223993.73 | R93: 66258.5 | S93: 29921.091 | T93: 102224.61 | U93: 52804.247 | V93: 50754.415 | W93: 188303.36 | X93: 61244.166 | Y93: 834858.12 | Z93: 760172.97 | AA93: 398679.16 | AB93: 240328.66 | AC93: 623430.87 | AD93: 342172.92 | AE93: 392148.03 | AF93: 1507650.4 | AG93: 431512.36 | AH93: 2902990.8 | AI93: 82464.971 | AJ93: 320517.81 | AK93: 626062.23 | AL93: 648843.77 | AM93: 165846.89 | AN93: 30909.971 | AO93: 13163.998 | AP93: 391714.87 | AQ93: 278494.13 | AR93: 13167.815 | AS93: 2368.893 | AT93: 79658.586 | AU93: 935.806 | AV93: 24642.477 | AW93: 35558.921 | AX93: 16094.635 | AY93: 33649.853 | AZ93: 48932.571 | BA93: 190206.11 | BB93: 5152.618 | BC93: 1374.502 | BD93: 5059.089 | BE93: 261678.11 | BF93: 14563.345 | BG93: 203831.15 | BH93: 186828.1 | BI93: 33268.362 | BJ93: 400.259 | BK93: 150167.43 | BL93: 86875.743 | BM93: 226081.16 | BN93: 10800.066 | BO93: 141467.66 | BP93: 109980.92 | BQ93: 175589.12 | BR93: 1820.333 | BS93: 17741.36 | BT93: 15023.726 | BU93: 5255.977 | BV93: 43343.499 | BW93: 151005.66 | BX93: 195232.01 | BY93: 88786.974 | BZ93: 47700.029 | CA93: 26303.388 | CB93: 0 | CC93: 450565.84 | CD93: 24176670 | CE93: 16292903 | CF93: 2721397.8 | CG93: 5572111.5 | CH93: 103964.58 | CI93: 9439522.4 | CJ93: -9953228.4 | CK93: 0
A94: B.1bV - Valor agregado bruto | C94: 22873646 | D94: 516354.55 | E94: 242533.1 | F94: 22690.785 | G94: 9602.663 | H94: 5913.921 | I94: 621540.6 | J94: 265067.55 | K94: 61718.433 | L94: 456907.22 | M94: 1064926.3 | N94: 214062.02 | O94: 181801.25 | P94: 911713.77 | Q94: 240174.37 | R94: 32513.579 | S94: 17328.629 | T94: 71182.811 | U94: 31436.957 | V94: 38837.812 | W94: 101611.97 | X94: 24643.809 | Y94: 164436.95 | Z94: 356405.6 | AA94: 151603.43 | AB94: 157596.1 | AC94: 257274.88 | AD94: 170712.28 | AE94: 208837.09 | AF94: 409294.66 | AG94: 178614.03 | AH94: 1168500.8 | AI94: 55539.633 | AJ94: 132857.27 | AK94: 2268261.4 | AL94: 2241444.5 | AM94: 63574.495 | AN94: 38500.664 | AO94: 18964.174 | AP94: 856330.64 | AQ94: 451171.37 | AR94: 12751.734 | AS94: 2487.176 | AT94: 154556.62 | AU94: 3961.699 | AV94: 21564.182 | AW94: 29847.125 | AX94: 16348.493 | AY94: 36940.5 | AZ94: 41617.767 | BA94: 266493.91 | BB94: 8319.393 | BC94: 1540.617 | BD94: 38078.365 | BE94: 678782.23 | BF94: 22931.666 | BG94: 146867.75 | BH94: 2036876.9 | BI94: 34210.342 | BJ94: 49572.822 | BK94: 435679.6 | BL94: 126888.46 | BM94: 778751.55 | BN94: 14765.428 | BO94: 877924.17 | BP94: 245527.75 | BQ94: 283184.08 | BR94: 2758.547 | BS94: 16206.956 | BT94: 51526.702 | BU94: 7531.426 | BV94: 56466.616 | BW94: 254701.17 | BX94: 329273.32 | BY94: 118399.89 | BZ94: 175693.32 | CA94: 56696.528 | CB94: 100065.29 | CC94: 855373.41
A95: P.1 - Producción | C95: 41959242 | D95: 682846.43 | E95: 495469.19 | F95: 28827.855 | G95: 22972.495 | H95: 10393.96 | I95: 886533.21 | J95: 421712.98 | K95: 152934.19 | L95: 735834.91 | M95: 2090312.5 | N95: 568177.3 | O95: 304773.24 | P95: 2391061.4 | Q95: 464168.1 | R95: 98772.079 | S95: 47249.72 | T95: 173407.42 | U95: 84241.204 | V95: 89592.227 | W95: 289915.33 | X95: 85887.975 | Y95: 999295.07 | Z95: 1116578.6 | AA95: 550282.59 | AB95: 397924.76 | AC95: 880705.75 | AD95: 512885.2 | AE95: 600985.12 | AF95: 1916945 | AG95: 610126.4 | AH95: 4071491.5 | AI95: 138004.6 | AJ95: 453375.08 | AK95: 2894323.7 | AL95: 2890288.2 | AM95: 229421.39 | AN95: 69410.635 | AO95: 32128.172 | AP95: 1248045.5 | AQ95: 729665.5 | AR95: 25919.549 | AS95: 4856.069 | AT95: 234215.2 | AU95: 4897.505 | AV95: 46206.659 | AW95: 65406.046 | AX95: 32443.128 | AY95: 70590.353 | AZ95: 90550.338 | BA95: 456700.01 | BB95: 13472.011 | BC95: 2915.119 | BD95: 43137.454 | BE95: 940460.33 | BF95: 37495.011 | BG95: 350698.9 | BH95: 2223705 | BI95: 67478.704 | BJ95: 49973.081 | BK95: 585847.03 | BL95: 213764.2 | BM95: 1004832.7 | BN95: 25565.494 | BO95: 1019391.8 | BP95: 355508.67 | BQ95: 458773.2 | BR95: 4578.88 | BS95: 33948.316 | BT95: 66550.428 | BU95: 12787.403 | BV95: 99810.115 | BW95: 405706.83 | BX95: 524505.33 | BY95: 207186.86 | BZ95: 223393.35 | CA95: 82999.916 | CB95: 100065.29 | CC95: 1305939.3
A96: B.1bP - Producto interno bruto | B96: 24176670 | C96: 23186147 | D96: 517661.45 | E96: 242840.56 | F96: 22747.165 | G96: 9813.273 | H96: 5944.97 | I96: 624333.09 | J96: 269358.54 | K96: 63731.368 | L96: 479465.98 | M96: 1067907.6 | N96: 217605.99 | O96: 182150.89 | P96: 918185.97 | Q96: 241654.59 | R96: 32698.105 | S96: 17424.34 | T96: 71561.515 | U96: 31601.17 | V96: 38981.505 | W96: 102680.45 | X96: 25065.137 | Y96: 238703.56 | Z96: 366426.41 | AA96: 153530.31 | AB96: 159308.98 | AC96: 259583.95 | AD96: 172004.62 | AE96: 209397.7 | AF96: 410128.39 | AG96: 179282.39 | AH96: 1173783.2 | AI96: 55774.345 | AJ96: 133167.89 | AK96: 2283072 | AL96: 2250225.4 | AM96: 73475.412 | AN96: 39646.294 | AO96: 19503.282 | AP96: 869055.43 | AQ96: 460486.83 | AR96: 12951.867 | AS96: 2545.84 | AT96: 155061.32 | AU96: 3912.055 | AV96: 22168.499 | AW96: 30160.962 | AX96: 16416.918 | AY96: 37150.635 | AZ96: 41718.582 | BA96: 267249.63 | BB96: 8331.722 | BC96: 1569.38 | BD96: 38030.509 | BE96: 678439.33 | BF96: 22972.478 | BG96: 146435.14 | BH96: 2038914.7 | BI96: 34491.974 | BJ96: 49577.746 | BK96: 437559.9 | BL96: 128043.75 | BM96: 780143.28 | BN96: 14827.526 | BO96: 886655.66 | BP96: 252262.12 | BQ96: 291560.16 | BR96: 2786.691 | BS96: 16953.331 | BT96: 52056.894 | BU96: 7797.369 | BV96: 57046.436 | BW96: 261733.43 | BX96: 335605.05 | BY96: 118582.66 | BZ96: 175860.89 | CA96: 56783.921 | CB96: 100065.29 | CC96: 911752.88 | CD96: 990523.79 | CE96: 951517.03 | CF96: 0 | CG96: 39006.587 | CH96: 0 | CI96: 0.177 | CJ96: 0 | CK96: 0
A97: __cD.1 - Remuneración de los asalariados | C97: 5974564.1 | D97: 81952.982 | E97: 43031.241 | F97: 737.32 | G97: 3298.361 | H97: 1494.103 | I97: 31707.356 | J97: 34467.606 | K97: 5404.55 | L97: 80611.858 | M97: 306662.64 | N97: 47285.398 | O97: 40442.471 | P97: 101965.91 | Q97: 22523.696 | R97: 10797.038 | S97: 6271.621 | T97: 29620.008 | U97: 14107.86 | V97: 10442.215 | W97: 20457.367 | X97: 10714.06 | Y97: 17586.133 | Z97: 60324.339 | AA97: 45326.683 | AB97: 25120.79 | AC97: 24772.187 | AD97: 53298.487 | AE97: 58863.988 | AF97: 191288.82 | AG97: 59237.737 | AH97: 170394.67 | AI97: 22042.646 | AJ97: 51567.494 | AK97: 92635.907 | AL97: 481440.27 | AM97: 14192.194 | AN97: 4005.537 | AO97: 3476.737 | AP97: 149044.31 | AQ97: 167321.96 | AR97: 2463.319 | AS97: 953.773 | AT97: 28166.273 | AU97: 3663.679 | AV97: 8213.066 | AW97: 14327.91 | AX97: 5852.123 | AY97: 5883.84 | AZ97: 2560.248 | BA97: 49401.885 | BB97: 2601.818 | BC97: 611.295 | BD97: 2586 | BE97: 163352.3 | BF97: 6203.965 | BG97: 33450.742 | BH97: 48351.87 | BI97: 5260.59 | BJ97: 94.009 | BK97: 141873.22 | BL97: 19319.039 | BM97: 489320.16 | BN97: 3815.52 | BO97: 756662.08 | BP97: 168780.85 | BQ97: 249279.04 | BR97: 2222.713 | BS97: 9365.764 | BT97: 16104.22 | BU97: 6455.413 | BV97: 10525.85 | BW97: 49994.966 | BX97: 70204.152 | BY97: 24456.583 | BZ97: 17336.449 | CA97: 25190.881 | CB97: 100065.29 | CC97: 833656.71
A98: D.11 - Sueldos y salarios | C98: 4889091.2 | D98: 81952.982 | E98: 42849.339 | F98: 737.32 | G98: 2998.863 | H98: 1285.253 | I98: 26914.038 | J98: 26518.322 | K98: 4641.092 | L98: 74736.36 | M98: 287809.38 | N98: 39374.138 | O98: 37804.952 | P98: 84080.996 | Q98: 17605.641 | R98: 8890.853 | S98: 5342.402 | T98: 24918.473 | U98: 11916.927 | V98: 9376.159 | W98: 15799.88 | X98: 8776.82 | Y98: 8632.955 | Z98: 36132.604 | AA98: 35322.325 | AB98: 18777.224 | AC98: 16575.587 | AD98: 41773.586 | AE98: 41500.406 | AF98: 145311.2 | AG98: 40696.154 | AH98: 122065.33 | AI98: 18444.418 | AJ98: 40220.072 | AK98: 77519.531 | AL98: 427135.59 | AM98: 12209.939 | AN98: 2960.594 | AO98: 2747.812 | AP98: 122553.5 | AQ98: 155578.3 | AR98: 2074.385 | AS98: 922.676 | AT98: 22181.064 | AU98: 3137.786 | AV98: 5793.328 | AW98: 11651.682 | AX98: 4693.139 | AY98: 4803.111 | AZ98: 2143.51 | BA98: 35973.282 | BB98: 2288.636 | BC98: 426.267 | BD98: 1970 | BE98: 132396.52 | BF98: 5314.071 | BG98: 28196.328 | BH98: 41978.97 | BI98: 3926.024 | BJ98: 84.395 | BK98: 119003.79 | BL98: 10740.822 | BM98: 387623.84 | BN98: 3156.154 | BO98: 638785 | BP98: 120209.57 | BQ98: 152118.75 | BR98: 1826.658 | BS98: 7058.405 | BT98: 15012.547 | BU98: 4789.237 | BV98: 8713.785 | BW98: 41367.996 | BX98: 63216.225 | BY98: 21037.554 | BZ98: 16097.381 | CA98: 23464.444 | CB98: 100065.29 | CC98: 664361.26
A99: D.11_1 - Salarios | C99: 2613160 | D99: 81952.982 | E99: 42793.47 | F99: 737.32 | G99: 2891.846 | H99: 1117.799 | I99: 8544.188 | J99: 21819.321 | K99: 3701.432 | L99: 65104.482 | M99: 264066.59 | N99: 25617.465 | O99: 33228.838 | P99: 62342.684 | Q99: 12380.845 | R99: 7456.787 | S99: 4395.376 | T99: 21321.574 | U99: 9963.979 | V99: 8380.144 | W99: 10885.649 | X99: 6307.537 | Y99: 6296.585 | Z99: 23660.273 | AA99: 25272.132 | AB99: 14587.248 | AC99: 11409.396 | AD99: 28626.519 | AE99: 30211.872 | AF99: 109410.15 | AG99: 30159.433 | AH99: 92633.5 | AI99: 14601.376 | AJ99: 32265.817 | AK99: 63329.159 | AL99: 376259.03 | AM99: 9615.798 | AN99: 1911.636 | AO99: 2323.303 | AP99: 89600.398 | AQ99: 147553.67 | AR99: 1472.71 | AS99: 794.187 | AT99: 12556.525 | AU99: 1960.272 | AV99: 3782.522 | AW99: 7239.35 | AX99: 2750.442 | AY99: 2917.824 | AZ99: 1539.305 | BA99: 26169.241 | BB99: 1706.432 | BC99: 217.394 | BD99: 0 | BE99: 0 | BF99: 0 | BG99: 0 | BH99: 39305.884 | BI99: 3063.626 | BJ99: 84.395 | BK99: 65505.138 | BL99: 276.102 | BM99: 298992.46 | BN99: 2815.676 | BO99: 41941.842 | BP99: 13016.295 | BQ99: 13552.696 | BR99: 952.232 | BS99: 3524.63 | BT99: 10863.134 | BU99: 562.085 | BV99: 6680.732 | BW99: 32316.7 | BX99: 59205.34 | BY99: 18434.807 | BZ99: 14538.441 | CA99: 19618.67 | CB99: 100065.29 | CC99: 0
A100: D.11_2 - Sueldos | C100: 2275931.2 | D100: 0 | E100: 55.869 | F100: 0 | G100: 107.017 | H100: 167.454 | I100: 18369.85 | J100: 4699.001 | K100: 939.66 | L100: 9631.878 | M100: 23742.792 | N100: 13756.673 | O100: 4576.114 | P100: 21738.312 | Q100: 5224.796 | R100: 1434.066 | S100: 947.026 | T100: 3596.899 | U100: 1952.948 | V100: 996.015 | W100: 4914.231 | X100: 2469.283 | Y100: 2336.37 | Z100: 12472.331 | AA100: 10050.193 | AB100: 4189.976 | AC100: 5166.191 | AD100: 13147.067 | AE100: 11288.534 | AF100: 35901.05 | AG100: 10536.721 | AH100: 29431.831 | AI100: 3843.042 | AJ100: 7954.255 | AK100: 14190.372 | AL100: 50876.556 | AM100: 2594.141 | AN100: 1048.958 | AO100: 424.509 | AP100: 32953.098 | AQ100: 8024.64 | AR100: 601.675 | AS100: 128.489 | AT100: 9624.539 | AU100: 1177.514 | AV100: 2010.806 | AW100: 4412.332 | AX100: 1942.697 | AY100: 1885.287 | AZ100: 604.205 | BA100: 9804.041 | BB100: 582.204 | BC100: 208.873 | BD100: 1970 | BE100: 132396.52 | BF100: 5314.071 | BG100: 28196.328 | BH100: 2673.086 | BI100: 862.398 | BJ100: 0 | BK100: 53498.656 | BL100: 10464.72 | BM100: 88631.385 | BN100: 340.478 | BO100: 596843.16 | BP100: 107193.27 | BQ100: 138566.05 | BR100: 874.426 | BS100: 3533.775 | BT100: 4149.413 | BU100: 4227.152 | BV100: 2033.053 | BW100: 9051.296 | BX100: 4010.885 | BY100: 2602.747 | BZ100: 1558.94 | CA100: 3845.774 | CB100: 0 | CC100: 664361.26
A101: D.121 - Contribuciones sociales efectivas de los empleadores | C101: 721349.29 | D101: 0 | E101: 134.578 | F101: 0 | G101: 193.424 | H101: 155.89 | I101: 0 | J101: 2683.888 | K101: 543.742 | L101: 4721.06 | M101: 13208.656 | N101: 5437.468 | O101: 1845.496 | P101: 7792.903 | Q101: 1766.207 | R101: 1249.81 | S101: 497.838 | T101: 2877.592 | U101: 1426.857 | V101: 738.924 | W101: 2369.619 | X101: 1195.505 | Y101: 187.578 | Z101: 4839.962 | AA101: 4958.94 | AB101: 2113.412 | AC101: 3395.21 | AD101: 5709.041 | AE101: 8012.015 | AF101: 20521.104 | AG101: 7357.596 | AH101: 20233.586 | AI101: 2256.041 | AJ101: 5285.875 | AK101: 8587.786 | AL101: 34489.729 | AM101: 1196.227 | AN101: 833.202 | AO101: 18.797 | AP101: 17757.158 | AQ101: 7010.961 | AR101: 21.513 | AS101: 18.019 | AT101: 3673.055 | AU101: 516.38 | AV101: 1270.936 | AW101: 1080.858 | AX101: 689.527 | AY101: 706.848 | AZ101: 256.825 | BA101: 6517.641 | BB101: 126.076 | BC101: 98.367 | BD101: 265 | BE101: 17531.329 | BF101: 670.24 | BG101: 2868.132 | BH101: 4174.307 | BI101: 456.941 | BJ101: 8.483 | BK101: 13235.111 | BL101: 2940.951 | BM101: 27795.339 | BN101: 265.859 | BO101: 109787.8 | BP101: 47694.901 | BQ101: 92886.771 | BR101: 356.27 | BS101: 2184.338 | BT101: 893.773 | BU101: 1526.242 | BV101: 1079.377 | BW101: 5894.114 | BX101: 3504.925 | BY101: 1074.921 | BZ101: 951.061 | CA101: 1056.924 | CB101: 0 | CC101: 163666.46
A102: D.122 - Contribuciones sociales imputadas de los empleadores | C102: 364123.65 | D102: 0 | E102: 47.324 | F102: 0 | G102: 106.074 | H102: 52.96 | I102: 4793.318 | J102: 5265.396 | K102: 219.716 | L102: 1154.438 | M102: 5644.603 | N102: 2473.792 | O102: 792.023 | P102: 10092.014 | Q102: 3151.848 | R102: 656.375 | S102: 431.381 | T102: 1823.943 | U102: 764.076 | V102: 327.132 | W102: 2287.868 | X102: 741.735 | Y102: 8765.6 | Z102: 19351.773 | AA102: 5045.418 | AB102: 4230.154 | AC102: 4801.39 | AD102: 5815.86 | AE102: 9351.567 | AF102: 25456.52 | AG102: 11183.987 | AH102: 28095.75 | AI102: 1342.187 | AJ102: 6061.547 | AK102: 6528.59 | AL102: 19814.947 | AM102: 786.028 | AN102: 211.741 | AO102: 710.128 | AP102: 8733.658 | AQ102: 4732.694 | AR102: 367.421 | AS102: 13.078 | AT102: 2312.154 | AU102: 9.513 | AV102: 1148.802 | AW102: 1595.37 | AX102: 469.457 | AY102: 373.881 | AZ102: 159.913 | BA102: 6910.962 | BB102: 187.106 | BC102: 86.661 | BD102: 351 | BE102: 13424.442 | BF102: 219.654 | BG102: 2386.282 | BH102: 2198.593 | BI102: 877.625 | BJ102: 1.131 | BK102: 9634.314 | BL102: 5637.266 | BM102: 73900.984 | BN102: 393.507 | BO102: 8089.274 | BP102: 876.381 | BQ102: 4273.525 | BR102: 39.785 | BS102: 123.021 | BT102: 197.9 | BU102: 139.934 | BV102: 732.688 | BW102: 2732.856 | BX102: 3483.002 | BY102: 2344.108 | BZ102: 288.007 | CA102: 669.513 | CB102: 0 | CC102: 5628.988
A103: D.29-D.39 - Impuestos netos de subsidios sobre la producción | C103: 130685.83 | D103: 14.564 | E103: 6.923 | F103: 0.675 | G103: 0.636 | H103: 0.091 | I103: 2133.83 | J103: 1039.727 | K103: 367.109 | L103: 5730.517 | M103: 5014.547 | N103: 1516.221 | O103: 733.332 | P103: 5752.415 | Q103: 1081.842 | R103: 237.352 | S103: 113.46 | T103: 416.264 | U103: 202.473 | V103: 215.581 | W103: 696.895 | X103: 176.93 | Y103: 1379.21 | Z103: 2575.061 | AA103: 1323.485 | AB103: 955.264 | AC103: 2111.198 | AD103: 1231.899 | AE103: 1401.028 | AF103: 4578.872 | AG103: 1466.233 | AH103: 9791.465 | AI103: 332.12 | AJ103: 1086.948 | AK103: 7834.146 | AL103: 10878.935 | AM103: 552.204 | AN103: 167.065 | AO103: 290.527 | AP103: 2463.883 | AQ103: -5966.328 | AR103: 62.298 | AS103: 11.676 | AT103: 563.278 | AU103: 120.278 | AV103: 111.155 | AW103: 153.308 | AX103: 78.038 | AY103: 165.827 | AZ103: 186.414 | BA103: 1098.961 | BB103: 32.423 | BC103: 10.267 | BD103: 79 | BE103: 19653.374 | BF103: 293.732 | BG103: 616.487 | BH103: 4804.923 | BI103: 162.283 | BJ103: 120.289 | BK103: 1287.869 | BL103: 1507.53 | BM103: 2416.36 | BN103: 61.524 | BO103: 3987.759 | BP103: 1185.668 | BQ103: 1368.687 | BR103: 34.09 | BS103: 37.472 | BT103: 134.243 | BU103: 118.725 | BV103: 244.576 | BW103: 1058.294 | BX103: 1324.012 | BY103: 498.664 | BZ103: 314.884 | CA103: 199.784 | CB103: 0 | CC103: 16677.081
A104: D.29_ - Impuestos que gravan la actividad | C104: 138714.61 | D104: 14.564 | E104: 6.923 | F104: 0.675 | G104: 0.636 | H104: 0.091 | I104: 2133.83 | J104: 1039.727 | K104: 367.109 | L104: 5730.517 | M104: 5014.547 | N104: 1516.221 | O104: 733.332 | P104: 5752.415 | Q104: 1081.842 | R104: 237.352 | S104: 113.46 | T104: 416.264 | U104: 202.473 | V104: 215.581 | W104: 696.895 | X104: 176.93 | Y104: 1379.21 | Z104: 2575.061 | AA104: 1323.485 | AB104: 955.264 | AC104: 2111.198 | AD104: 1231.899 | AE104: 1401.028 | AF104: 4578.872 | AG104: 1466.233 | AH104: 9791.465 | AI104: 332.12 | AJ104: 1086.948 | AK104: 7834.146 | AL104: 10878.935 | AM104: 552.204 | AN104: 167.065 | AO104: 290.527 | AP104: 2463.883 | AQ104: 1754.646 | AR104: 62.298 | AS104: 11.676 | AT104: 563.278 | AU104: 120.278 | AV104: 111.155 | AW104: 153.308 | AX104: 78.038 | AY104: 165.827 | AZ104: 186.414 | BA104: 1098.961 | BB104: 32.423 | BC104: 10.267 | BD104: 79 | BE104: 19653.374 | BF104: 293.732 | BG104: 616.487 | BH104: 4804.923 | BI104: 162.283 | BJ104: 120.289 | BK104: 1595.669 | BL104: 1507.53 | BM104: 2416.36 | BN104: 61.524 | BO104: 3987.759 | BP104: 1185.668 | BQ104: 1368.687 | BR104: 34.09 | BS104: 37.472 | BT104: 134.243 | BU104: 118.725 | BV104: 244.576 | BW104: 1058.294 | BX104: 1324.012 | BY104: 498.664 | BZ104: 314.884 | CA104: 199.784 | CB104: 0 | CC104: 16677.081
A105: D.39_ - Menos: subsidios | C105: 8028.774 | D105: 0 | E105: 0 | F105: 0 | G105: 0 | H105: 0 | I105: 0 | J105: 0 | K105: 0 | L105: 0 | M105: 0 | N105: 0 | O105: 0 | P105: 0 | Q105: 0 | R105: 0 | S105: 0 | T105: 0 | U105: 0 | V105: 0 | W105: 0 | X105: 0 | Y105: 0 | Z105: 0 | AA105: 0 | AB105: 0 | AC105: 0 | AD105: 0 | AE105: 0 | AF105: 0 | AG105: 0 | AH105: 0 | AI105: 0 | AJ105: 0 | AK105: 0 | AL105: 0 | AM105: 0 | AN105: 0 | AO105: 0 | AP105: 0 | AQ105: 7720.974 | AR105: 0 | AS105: 0 | AT105: 0 | AU105: 0 | AV105: 0 | AW105: 0 | AX105: 0 | AY105: 0 | AZ105: 0 | BA105: 0 | BB105: 0 | BC105: 0 | BD105: 0 | BE105: 0 | BF105: 0 | BG105: 0 | BH105: 0 | BI105: 0 | BJ105: 0 | BK105: 307.8 | BL105: 0 | BM105: 0 | BN105: 0 | BO105: 0 | BP105: 0 | BQ105: 0 | BR105: 0 | BS105: 0 | BT105: 0 | BU105: 0 | BV105: 0 | BW105: 0 | BX105: 0 | BY105: 0 | BZ105: 0 | CA105: 0 | CB105: 0 | CC105: 0
A106: B.2b - Excedente bruto de operación | C106: 16768396 | D106: 434387.01 | E106: 199494.93 | F106: 21952.79 | G106: 6303.666 | H106: 4419.727 | I106: 587699.41 | J106: 229560.22 | K106: 55946.774 | L106: 370564.85 | M106: 753249.07 | N106: 165260.4 | O106: 140625.45 | P106: 803995.44 | Q106: 216568.83 | R106: 21479.189 | S106: 10943.548 | T106: 41146.539 | U106: 17126.624 | V106: 28180.016 | W106: 80457.71 | X106: 13752.819 | Y106: 145471.6 | Z106: 293506.2 | AA106: 104953.26 | AB106: 131520.05 | AC106: 230391.49 | AD106: 116181.89 | AE106: 148572.08 | AF106: 213426.96 | AG106: 117910.06 | AH106: 988314.62 | AI106: 33164.867 | AJ106: 80202.828 | AK106: 2167791.4 | AL106: 1749125.3 | AM106: 48830.097 | AN106: 34328.062 | AO106: 15196.91 | AP106: 704822.45 | AQ106: 289815.74 | AR106: 10226.117 | AS106: 1521.727 | AT106: 125827.07 | AU106: 177.742 | AV106: 13239.961 | AW106: 15365.907 | AX106: 10418.332 | AY106: 30890.833 | AZ106: 38871.105 | BA106: 215993.06 | BB106: 5685.152 | BC106: 919.055 | BD106: 35413.365 | BE106: 495776.56 | BF106: 16433.969 | BG106: 112800.52 | BH106: 1983720.1 | BI106: 28787.469 | BJ106: 49358.524 | BK106: 292518.51 | BL106: 106061.89 | BM106: 287015.03 | BN106: 10888.384 | BO106: 117274.34 | BP106: 75561.234 | BQ106: 32536.35 | BR106: 501.744 | BS106: 6803.72 | BT106: 35288.239 | BU106: 957.288 | BV106: 45696.19 | BW106: 203647.91 | BX106: 257745.16 | BY106: 93444.642 | BZ106: 158041.99 | CA106: 31305.863 | CB106: 0 | CC106: 5039.62
...

Sheet Replicate technical coeff
A1: Instituto Nacional de Estadística y Geografía (INEGI).
A2: Sistema de Cuentas Nacionales de México. Matriz de Insumo Producto simétrica, Base 2018
A3: Matriz simétrica de insumo producto. Industria por industria/ Economía total / Origen doméstico coeficientes técnicos/ Subsector SCIAN
A5: Concepto | B5: 111 - Agricultura | C5: 112 - Cría y explotación de animales | D5: 113 - Aprovechamiento forestal | E5: 114 - Pesca, caza y captura | F5: 115 - Servicios relacionados con las actividades agropecuarias y forestales | G5: 211 - Extracción de petróleo y gas | H5: 212 - Minería de minerales metálicos y no metálicos, excepto petróleo y gas | I5: 213 - Servicios relacionados con la minería | J5: 221 - Generación, transmisión, distribución y comercialización de energía eléctrica, suministro de agua y de gas natural por ductos al consumidor final | K5: 236 - Edificación | L5: 237 - Construcción de obras de ingeniería civil | M5: 238 - Trabajos especializados para la construcción | N5: 311 - Industria alimentaria | O5: 312 - Industria de las bebidas y del tabaco | P5: 313 - Fabricación de insumos textiles y acabado de textiles | Q5: 314 - Fabricación de productos textiles, excepto prendas de vestir | R5: 315 - Fabricación de prendas de vestir | S5: 316 - Curtido y acabado de cuero y piel, y fabricación de productos de cuero, piel y materiales sucedáneos | T5: 321 - Industria de la madera | U5: 322 - Industria del papel | V5: 323 - Impresión e industrias conexas | W5: 324 - Fabricación de productos derivados del petróleo y del carbón | X5: 325 - Industria química | Y5: 326 - Industria del plástico y del hule | Z5: 327 - Fabricación de productos a base de minerales no metálicos | AA5: 331 - Industrias metálicas básicas | AB5: 332 - Fabricación de productos metálicos | AC5: 333 - Fabricación de maquinaria y equipo | AD5: 334 - Fabricación de equipo de computación, comunicación, medición y de otros equipos, componentes y accesorios electrónicos | AE5: 335 - Fabricación de accesorios, aparatos eléctricos y equipo de generación de energía eléctrica | AF5: 336 - Fabricación de equipo de transporte | AG5: 337 - Fabricación de muebles, colchones y persianas | AH5: 339 - Otras industrias manufactureras | AI5: 431 - Comercio al por mayor de abarrotes, alimentos, bebidas, hielo y tabaco | AJ5: 461 - Comercio al por menor de abarrotes, alimentos, bebidas, hielo y tabaco | AK5: 481 - Transporte aéreo | AL5: 482 - Transporte por ferrocarril | AM5: 483 - Transporte por agua | AN5: 484 - Autotransporte de carga | AO5: 485 - Transporte terrestre de pasajeros, excepto por ferrocarril | AP5: 486 - Transporte por ductos | AQ5: 487 - Transporte turístico | AR5: 488 - Servicios relacionados con el transporte | AS5: 491 - Servicios postales | AT5: 492 - Servicios de mensajería y paquetería | AU5: 493 - Servicios de almacenamiento | AV5: 511 - Edición de periódicos, revistas, libros, software y otros materiales, y edición de estas publicaciones integrada con la impresión | AW5: 512 - Industria fílmica y del video, e industria del sonido | AX5: 515 - Radio y televisión | AY5: 517 - Telecomunicaciones | AZ5: 518 - Procesamiento electrónico de información, hospedaje y otros servicios relacionados | BA5: 519 - Otros servicios de información | BB5: 521 - Banca central | BC5: 522 - Instituciones de intermediación crediticia y financiera no bursátil | BD5: 523 - Actividades bursátiles, cambiarias y de inversión financiera | BE5: 524 - Compañías de seguros, fianzas, y administración de fondos para el retiro | BF5: 531 - Servicios inmobiliarios | BG5: 532 - Servicios de alquiler de bienes muebles | BH5: 533 - Servicios de alquiler de marcas registradas, patentes y franquicias | BI5: 541 - Servicios profesionales, científicos y técnicos | BJ5: 551 - Corporativos | BK5: 561 - Servicios de apoyo a los negocios | BL5: 562 - Manejo de residuos y servicios de remediación | BM5: 611 - Servicios educativos | BN5: 621 - Servicios médicos de consulta externa y servicios relacionados | BO5: 622 - Hospitales | BP5: 623 - Residencias de asistencia social y para el cuidado de la salud | BQ5: 624 - Otros servicios de asistencia social | BR5: 711 - Servicios artísticos, culturales y deportivos, y otros servicios relacionados | BS5: 712 - Museos, sitios históricos, zoológicos y similares | BT5: 713 - Servicios de entretenimiento en instalaciones recreativas y otros servicios recreativos | BU5: 721 - Servicios de alojamiento temporal | BV5: 722 - Servicios de preparación de alimentos y bebidas | BW5: 811 - Servicios de reparación y mantenimiento | BX5: 812 - Servicios personales | BY5: 813 - Asociaciones y organizaciones | BZ5: 814 - Hogares con empleados domésticos | CA5: 931 - Actividades legislativas, gubernamentales y de impartición de justicia
A6: 111 - Agricultura | B6: =Domestic!E7/Domestic!E$96 -> 0.019041663 | C6: =Domestic!F7/Domestic!F$96 -> 0.11379988 | D6: =Domestic!G7/Domestic!G$96 -> 0.0061249441 | E6: =Domestic!H7/Domestic!H$96 -> 0.00051679193 | F6: =Domestic!I7/Domestic!I$96 -> 0.030232558 | G6: =Domestic!J7/Domestic!J$96 -> 0 | H6: =Domestic!K7/Domestic!K$96 -> 0 | I6: =Domestic!L7/Domestic!L$96 -> 0 | ... CA6: =Domestic!CD7/Domestic!CD$96 -> 3.1286294e-05
A7: 112 - Cría y explotación de animales | B7: =Domestic!E8/Domestic!E$96 -> 0.0073783822 | C7: =Domestic!F8/Domestic!F$96 -> 0.023237824 | D7: =Domestic!G8/Domestic!G$96 -> 0 | E7: =Domestic!H8/Domestic!H$96 -> 0 | F7: =Domestic!I8/Domestic!I$96 -> 0 | G7: =Domestic!J8/Domestic!J$96 -> 9.0239146e-09 | H7: =Domestic!K8/Domestic!K$96 -> 2.371281e-09 | I7: =Domestic!L8/Domestic!L$96 -> 7.8465124e-08 | ... CA7: =Domestic!CD8/Domestic!CD$96 -> 2.5261512e-06
A8: 113 - Aprovechamiento forestal | B8: =Domestic!E9/Domestic!E$96 -> 0 | C8: =Domestic!F9/Domestic!F$96 -> 0 | D8: =Domestic!G9/Domestic!G$96 -> 0.043810405 | E8: =Domestic!H9/Domestic!H$96 -> 0 | F8: =Domestic!I9/Domestic!I$96 -> 5.4839541e-06 | G8: =Domestic!J9/Domestic!J$96 -> 0 | H8: =Domestic!K9/Domestic!K$96 -> 1.5911296e-06 | I8: =Domestic!L9/Domestic!L$96 -> 0 | ... CA8: =Domestic!CD9/Domestic!CD$96 -> 0
A9: 114 - Pesca, caza y captura | B9: =Domestic!E10/Domestic!E$96 -> 0 | C9: =Domestic!F10/Domestic!F$96 -> 6.4585247e-08 | D9: =Domestic!G10/Domestic!G$96 -> 5.8970742e-07 | E9: =Domestic!H10/Domestic!H$96 -> 0.00070305816 | F9: =Domestic!I10/Domestic!I$96 -> 6.7346805e-07 | G9: =Domestic!J10/Domestic!J$96 -> 2.4138971e-06 | H9: =Domestic!K10/Domestic!K$96 -> 8.2283452e-07 | I9: =Domestic!L10/Domestic!L$96 -> 2.0937111e-05 | ... CA9: =Domestic!CD10/Domestic!CD$96 -> 4.2329687e-06
A10: 115 - Servicios relacionados con las actividades agropecuarias y forestales | B10: =Domestic!E11/Domestic!E$96 -> 0.0056527395 | C10: =Domestic!F11/Domestic!F$96 -> 0.0014727515 | D10: =Domestic!G11/Domestic!G$96 -> 0.0026827872 | E10: =Domestic!H11/Domestic!H$96 -> 0.0008452717 | F10: =Domestic!I11/Domestic!I$96 -> 2.5110737e-05 | G10: =Domestic!J11/Domestic!J$96 -> 1.8047829e-08 | H10: =Domestic!K11/Domestic!K$96 -> 7.1138431e-09 | I10: =Domestic!L11/Domestic!L$96 -> 6.5387604e-09 | ... CA10: =Domestic!CD11/Domestic!CD$96 -> 4.3263881e-07
A11: 211 - Extracción de petróleo y gas | B11: =Domestic!E12/Domestic!E$96 -> 6.4685115e-06 | C11: =Domestic!F12/Domestic!F$96 -> 1.6261354e-05 | D11: =Domestic!G12/Domestic!G$96 -> 4.1279519e-06 | E11: =Domestic!H12/Domestic!H$96 -> 9.4896092e-06 | F11: =Domestic!I12/Domestic!I$96 -> 8.0816166e-06 | G11: =Domestic!J12/Domestic!J$96 -> 4.0912173e-06 | H11: =Domestic!K12/Domestic!K$96 -> 4.1473706e-06 | I11: =Domestic!L12/Domestic!L$96 -> 5.8979618e-06 | ... CA11: =Domestic!CD12/Domestic!CD$96 -> 2.2573791e-06
A12: 212 - Minería de minerales metálicos y no metálicos, excepto petróleo y gas | B12: =Domestic!E13/Domestic!E$96 -> 0.00075139296 | C12: =Domestic!F13/Domestic!F$96 -> 0.00040295745 | D12: =Domestic!G13/Domestic!G$96 -> 0.00054599969 | E12: =Domestic!H13/Domestic!H$96 -> 0.00059423236 | F12: =Domestic!I13/Domestic!I$96 -> 0.00019434364 | G12: =Domestic!J13/Domestic!J$96 -> 0.00083997755 | H12: =Domestic!K13/Domestic!K$96 -> 0.0098084104 | I12: =Domestic!L13/Domestic!L$96 -> 0.0021631985 | ... CA12: =Domestic!CD13/Domestic!CD$96 -> 0.00033834652
A13: 213 - Servicios relacionados con la minería | B13: =Domestic!E14/Domestic!E$96 -> 0 | C13: =Domestic!F14/Domestic!F$96 -> 1.4128023e-08 | D13: =Domestic!G14/Domestic!G$96 -> 7.9783945e-07 | E13: =Domestic!H14/Domestic!H$96 -> 4.7883349e-07 | F13: =Domestic!I14/Domestic!I$96 -> 4.8104861e-07 | G13: =Domestic!J14/Domestic!J$96 -> 0.0035008784 | H13: =Domestic!K14/Domestic!K$96 -> 0.00071178032 | I13: =Domestic!L14/Domestic!L$96 -> 0.00028719543 | ... CA13: =Domestic!CD14/Domestic!CD$96 -> 5.7766852e-06
A14: 221 - Generación, transmisión, distribución y comercialización de energía eléctrica, suministro de agua y de gas natural por ductos al consumidor final | B14: =Domestic!E15/Domestic!E$96 -> 0.015589173 | C14: =Domestic!F15/Domestic!F$96 -> 0.010828849 | D14: =Domestic!G15/Domestic!G$96 -> 0.0035911101 | E14: =Domestic!H15/Domestic!H$96 -> 0.004125847 | F14: =Domestic!I15/Domestic!I$96 -> 0.015860076 | G14: =Domestic!J15/Domestic!J$96 -> 0.0036380679 | H14: =Domestic!K15/Domestic!K$96 -> 0.032504178 | I14: =Domestic!L15/Domestic!L$96 -> 0.039817225 | ... CA14: =Domestic!CD15/Domestic!CD$96 -> 0.012008737
A15: 236 - Edificación | B15: =Domestic!E16/Domestic!E$96 -> 1.7286464e-05 | C15: =Domestic!F16/Domestic!F$96 -> 3.5655093e-05 | D15: =Domestic!G16/Domestic!G$96 -> 5.2345206e-05 | E15: =Domestic!H16/Domestic!H$96 -> 0.00026657966 | F15: =Domestic!I16/Domestic!I$96 -> 9.4093108e-05 | G15: =Domestic!J16/Domestic!J$96 -> 0.00049823288 | H15: =Domestic!K16/Domestic!K$96 -> 0.00061802698 | I15: =Domestic!L16/Domestic!L$96 -> 0.0025510189 | ... CA15: =Domestic!CD16/Domestic!CD$96 -> 0.00045795775
A16: 237 - Construcción de obras de ingeniería civil | B16: =Domestic!E17/Domestic!E$96 -> 1.2980957e-05 | C16: =Domestic!F17/Domestic!F$96 -> 2.5775568e-05 | D16: =Domestic!G17/Domestic!G$96 -> 9.1890292e-05 | E16: =Domestic!H17/Domestic!H$96 -> 0.00027297862 | F16: =Domestic!I17/Domestic!I$96 -> 0.00010640795 | G16: =Domestic!J17/Domestic!J$96 -> 0.0006490349 | H16: =Domestic!K17/Domestic!K$96 -> 0.00064090273 | I16: =Domestic!L17/Domestic!L$96 -> 0.0038973496 | ... CA16: =Domestic!CD17/Domestic!CD$96 -> 0.00070322949
A17: 238 - Trabajos especializados para la construcción | B17: =Domestic!E18/Domestic!E$96 -> 1.1572148e-05 | C17: =Domestic!F18/Domestic!F$96 -> 4.3239823e-05 | D17: =Domestic!G18/Domestic!G$96 -> 0.044530368 | E17: =Domestic!H18/Domestic!H$96 -> 3.7914907e-05 | F17: =Domestic!I18/Domestic!I$96 -> 0.001167505 | G17: =Domestic!J18/Domestic!J$96 -> 0.00018711651 | H17: =Domestic!K18/Domestic!K$96 -> 0.011618068 | I17: =Domestic!L18/Domestic!L$96 -> 0.0076611582 | ... CA17: =Domestic!CD18/Domestic!CD$96 -> 0.0081878341
... A83: 931 - Actividades legislativas, gubernamentales y de impartición de justicia | B83: =Domestic!E84/Domestic!E$96 -> 0 | C83: =Domestic!F84/Domestic!F$96 -> 0 | D83: =Domestic!G84/Domestic!G$96 -> 0 | E83: =Domestic!H84/Domestic!H$96 -> 0 | F83: =Domestic!I84/Domestic!I$96 -> 0 | G83: =Domestic!J84/Domestic!J$96 -> 0 | H83: =Domestic!K84/Domestic!K$96 -> 0 | I83: =Domestic!L84/Domestic!L$96 -> 0 | ... CA83: =Domestic!CD84/Domestic!CD$96 -> 0
